Workbook

Sheet 900条整合编码
A1: 评论编号 | B1: 语言组 | C1: Steam推荐状态 | D1: 有价值人数 | E1: 欢乐人数 | F1: 游戏时长(小时) | G1: 发表时间 | H1: 原文 | I1: 中文译文/分析文本 | J1: A_视听表现 | K1: B_战斗操作 | L1: C_探索设计 | M1: D_技术稳定 | N1: E_整体评价 | O1: F_文化接近性 | P1: G_文化折扣/理解障碍 | Q1: H_国产3A/身份期待 | R1: A1_画面美术场景 | S1: A2_音乐音效配音 | T1: A3_演出角色怪物设计 | U1: B1_动作打击手感 | V1: B2_Boss战斗节奏 | W1: B3_难度挑战 | X1: B4_锁定视角 | Y1: B5_判定反馈 | Z1: C1_地图路线 | AA1: C2_空气墙可达性 | AB1: C3_探索隐藏支线 | AC1: C4_引导迷路单线 | AD1: D1_优化帧率 | AE1: D2_崩溃闪退 | AF1: D3_Bug兼容硬件 | AG1: E1_整体完成度 | AH1: E2_推荐价值判断 | AI1: F1_西游悟空符号 | AJ1: F2_童年记忆情怀 | AK1: F3_本国媒介路径 | AL1: F4_中国文化宗教语言审美 | AM1: G1_剧情叙事理解 | AN1: G2_原典知识人物关系专名 | AO1: G3_本地化翻译 | AP1: G4_外部资料依赖 | AQ1: G5_角色期待意义偏移 | AR1: H1_国产3A身份期待 | AS1: 一级编码数 | AT1: 二级编码数 | AU1: 二级编码标签 | AV1: 有编码 | AW1: 未命中 | AX1: 多主题 | AY1: 词典情感分值 | AZ1: 情感类别（自动） | BA1: 情感字母 | BB1: 计分文本来源
A2: CN-P-001 | B2: 中文 | C2: 推荐 | D2: 746 | E2: 18 | F2: 7.4 | G2: 2024-08-20 | H2: 《黑神话:悟空》对我们这代长年接触单机游戏，但往往只有欧美和日厂游戏可玩的玩家而言，真可谓是一剂强心剂。尽管近些年来优秀的国产独立游戏层出不穷，其中不乏同样能体现中华文化的佳作，但国人心中始终心怀一个梦想，“要有国产3A游戏就好了”。可能单从游戏性上规格体量高的游戏也并不能说明什么，但这却的的确确是游戏工业化的一大标签，对于突破国界向世界展现文化影响力而言，高规格游戏也有其不可替代性，从没有一个国家的玩家会整日将如“3A游戏”的词汇挂在嘴边，足可见他们的渴望。就在这如同荒漠渴望雨水时，2020年8月20日，大圣踩着筋斗云出现了 四年之约终有期 我第一次看见游戏PV时还是在大学时期，大圣变为一只金蝉进入黑风山，在就像是人参成精的土地公公指引下，进入观音禅院挑战被玩家戏称为“毛多弱火”的灵虚子。这一段预告相当激励人心，和国外一线大作肉眼几乎看不出明显差距的超强画面表现力，让无数国人玩家深藏在心中的梦想悄然间长出萌芽。毕竟相较于国外的蝙蝠侠、蜘蛛侠、美国队长等诸多有着超能力的硬汉，齐天大圣才一直是我们孩童时期的幻想，属于我们自己的超级英雄！而在高规格的游戏画面里耳边响起经典的“云宫迅音”，眼前是大圣的金箍棒，我至今难以忘记当初随着音乐鼓点颤动的心跳 但PV毕竟只是PV，我虽然在之后的每次观看黑神话预告时都还是会“焚香沐浴”一番，戴上耳机端坐在电脑前，而不会只是在手机小屏幕上观看，但在黑神话这四年时间的前后，数个尽管影响力没有这般大但同样相对高规格的国产游戏，或上线后褒贬不一、有限销量然后道歉下架绝版喜加一，要么干脆的胎死腹中，网上留存的也仅有一些片段。从以前的国产EA阶段游戏不可信、到现在的高规格游戏个个难产，让其声誉降至谷底，导致我其实对《黑神话:悟空》也难提起更多信心，说到底，这毕竟只是游戏科学团队应对如此体量作品的处女作，一个从未统筹过如此大项目的团队，甚至第一个PV的初衷还更多是因为团队缺人的缘故，面对如此这般泼天的流量和关注，是否能静下心来、保持初心的好好做游戏，对此我始终心存疑虑，更惶恐这如果真是一场“诈骗”对目前纤柔的萌芽阶段会是怎样一个毁灭性打击 2024年8月20日，没有跳票的，《黑神话:悟空》如期上线了。其实就在几天前的性能测试工具开放时，我这颗忐忑的心就放下了大半，一个如此有信心，在游戏开售前弄个测试工具事先应对玩家对游戏优化的疑虑，实际测试结果对中低端硬件的明显包容，很难让人不相信，游戏科学团队的确也已做好万全准备。而面对游戏发售前的泄露事件，制作人冯骥老师更是直接坦言道 最后，我依然很有信心，无论你（无意或是被迫）提前看过了多少已经泄露的内容，这个游戏仍然会带给你从未有过的感受与足够独特的乐趣。所以，不必担心，不必懊恼，《黑神话：悟空》没那么脆弱 是的，我相信《黑神话:悟空》没有这么脆弱，我相信这会是款足够好玩的游戏，不用媒体评分，不用看泄露视频，越临近答案揭晓的时刻，我越有信心，我从未如此笃定过 沉醉不知归路 不管是在过去观看预告PV的“云游戏”，还是此次自己的上手体验。《黑神话:悟空》那别具一格的、带有强烈东方元素的高级审美，都令我印象深刻。在如无头苍蝇般瞎转悠的同时，我总是被美好景致所感染的不由自主的停下前进探索的脚步，感受身边的风声蝉鸣、小桥流水和小妖怪的窃窃私语，观察着天边的第一缕阳光穿过大树的翠绿落到蒲团上，身边残破锈迹斑斑的佛陀像的双眼似乎尽显世态炎凉，自然风貌和人文建筑历经沧桑带来同样厚重感的和谐，这都是此前难以在其他国家的游戏作品中感受到的东方风韵，不需任何言语的堆砌，这种文化魅力只需要你站在那里，就会被深深的感染到 不过，在于光影的协调上不知道是不是因为我个人设置的关系，感觉存在一些小瑕疵。忽明忽暗的场景色调变化的较为频繁，不时的出现一些场景要么昏暗到影响探索，只能依赖于什么时候撞到空气墙然后亦步亦趋的继续，要么离开昏暗场景时瞬时的光暗反差表现过于明显到甚至有点晃眼。不少玩家认为这很有些“现实感”，我姑且认为这是调侃，毕竟这在美术表现如此高格调时所出现的一点点不良体验都足够明显 也正因为如此，《黑神话:悟空》也是我认为的相当适合如《刺客信条:起源》和《刺客信条:奥德赛》做个如“探索之旅”般，玩家只需要当个步行模拟器游玩的模式的游戏。并且，在游戏破圈后势必会有大量此前从未接触过ARPG游戏的轻度玩家，虽然并非说《黑神话:悟空》只有什么硬核高玩才能玩的下去，只是说，对于那部分可能对自己没什么信心，只是单纯想购买游戏权做支持的玩家而言，引入这样的探索模式对于他们来说，是个门槛几近于无的同时，能通过电子游戏感受这一份东方美学和文化浸染的好机会。而对于我们国家当前这个市场，尽可能多的加深游戏“文化赋分”的内容，强化更多正向的帽子，也不失为是件可以摆在台面上大肆宣传的好事 看我棍棒之下无一合之敌！ 此部分想从ARPG游戏的ACT和RPG两部分稍微展开来说一下 不得不承认，在同类游戏如此多的情况下，作为后来者《黑神话:悟空》的战斗系统还是做的很有特色。玩家主要需要通过轻重攻击来打伤害，轻攻击积累棍势，重攻击蓄力和切手技消耗棍势。除了初始的更适合追击敌人的劈棍式，还有可以将棍子撑长伫在原地然后狠狠下劈的立棍式和站在原地用长棍狠戳对面的戳棍式，三种不同的棍法也有着各自不同的延伸可供加点成长的技能点，从而产生不同的应对策略和派生流派 此外，还有诸如定身术的法术深化了悟空特色的战斗方式，随流程推进逐步解锁的诸般新法术新能力鼓励玩家尝试不同的方式战胜强敌。类同大圣七十二般变化的变身系统更让战斗的花样性有着很强的提升，虽然我个人操作有限更多时候都只能将变身期间当做肉盾扛血的休息间隙，但哪怕是最初的刀郎教头广智许多玩家也能利用好变身期间一下子打空boss们大半管血 至于和变化相似的“精魄”，玩家可以在打败精英小BOSS后，用葫芦吸收其精魄，然后在战斗中可以使出它们经典招式的一击。但老实说，我觉得“精魄”在自成体系的战斗系统中显得有些冗余，在对战中由于CD过长且作用着实有限，“精魄”的存在感属实不高，倒是在某些场合的功能性更为突出，比如可以用幽魂的捶地一击打破墙壁。不得不怀疑起初游科想的是将这些统统归到七十二变的变化中，或是工作量过大的缘故，其中的大部分变化被简化成“精魄”，让此多少显得有些格格不入 至于ARPG中的养成部分，其实《黑神话：悟空》这方面的内容较为常规，数值变化除了等级提升外的加点，更多的是通过装备属性上的加成，但装备属性的选择实则并不太自由，随阶段逐步解锁升级的装备让不同玩家之间的选择差异性也较为有限，而在某些阶段过快的装备套装更迭速度，让有些时候玩家容易产生“之前花了资源升级的某套装备好浪费，数值没提升多少不如留着升这套”的不良情绪 在BOSS Rush的路上处处碰“壁” 《黑神话：悟空》在关卡式分章节体的多张地图里塞满了各种的BOSS，按照其他玩家所说数量高达81只对应西行路上的九九八十一难，极度的堆量程度浪费到在只要不迷路的情况下往往走上几步路就要面对一只全新机制、此前从未接触过的新BOSS，更别提每一只BOSS所对应的各式场景和华丽演出，虽然有些时候因为尚未摸清套路显得有些受苦，但操控着“天命人”全情投入克服此前自以为难以逾越的困难，也自会产生成就感并更有勇气面对接下来遇到的其他“难” 战斗，爽！ 在BOSS战时视角的智能锁定成为一个问题，我因为时间有限攻略的内容不太多，关于视角问题印象很深的是在第一章关底，挑战黑熊精时，因为其庞大的体型，我在多数锁定视角下仅仅能看得到黑熊精的脚和满屏幕的黑毛，这也就导致在躲避伤害时我只能凭借此前黑熊精的攻击间隔猜测——它的下一招该出招了，或许我该躲了 而这也不仅仅是面对体型巨大的敌人会存在的视角问题，种类数量如此庞大的BOSS们，有龙跃于天的，有快速移动的，如果视角不是足够的智能，那对玩家的战斗体验多多少少会存在一些影响 在塞满BOSS的西行路上，很大一部分的BOSS并不是在主线道路上，玩家往往需要完成各种隐藏内容才能解锁，许多玩家一周目初见不看攻略通关后会赫然发现，许多的BOSS甚至都没有见到过 在大量隐藏内容之下，游戏关卡内分布较为密集的空气墙对玩家的探索造成了较负面的影响。《黑神话：悟空》并非是款开放世界的游戏，有空气墙倒逼玩家往设计好的道路上探索这无可厚非，但在一些看起来明显能走的道路上，却布好空气墙阻碍玩家前进，当这样的经历多次出现，很难说玩家能提起足够的心气在地图上尽情探索，寻找潜藏着隐藏内容。过分的限制玩家探索和塞满隐藏内容之间，这本就存在矛盾 在逼迫玩家“不撞南墙不回头”时，游戏的许多场景也缺失了必要的指引，有且仅有在附近有土地庙时我观察到在指引上有着些许设计。我丝毫不怀疑许多方向感比较强的“天命人”对此感觉毫无障碍，但对我这般麋鹿选手，在没有地图和适时指引且周边场景无明显地标之下，玩了一小时走回到了初遇的土地庙也并不新奇 重走西行路，再临九九八十一难 作为一部《西游记》后传作品，《黑神话：悟空》保持着严肃的改编风格，对自己理解的《西游记》做出了自己合乎逻辑自洽的注解，这让游戏并非只是成为一款简单的“Boss Rush”游戏，每一句台词，甚至于每一种小妖的图鉴都值得玩家细细揣摩，通过对原著的极致理解，通过大量自己的刻画，通过寥寥数笔描绘出了数个经典人物，并适时的引入包括“天命人”在内的全新设定却不显违和，就好像故事天然的就应该这么走下去 其实，设身处地的想，如果我是一名外国人，玩到《黑神话：悟空》这样的游戏，虽然依旧觉得好玩，但由于缺乏了那股子土生土长的文化浸染力，在游戏内容设计之外处处透着难以理解的排斥感，恐怕这也只是会成为我生命中一过客的游戏，和其他的动作游戏并没有太大的不同 但站在现下的这个时代背景下，国内单机游戏市场称之为荒漠虽然有些夸张但还是挺有现实性的，此时出现了一款游戏，将中国人耳熟能详的故事搬进每个玩家的荧幕前，熟悉的角色操着地道的口音，一进游戏默认的中文字幕中文配音，而老外却要苦恼有时候莫名出现BUG英文配音丢失 从想玩游戏没地方玩到处找资源，到找到资源了苦等汉化组出汉化。从终于有许多游戏玩了但都是海外游戏，到今天的国产游戏也证明了它不是丝毫没有可取之处。这条路我们走的好累，但终于见到了荒漠中的翠绿萌芽。《黑神话：悟空》于国人玩家而言远不是一款游戏这么简单，在移动端收益已进入下降趋势，手游的研发、发行、运营也变成一个“卷”且“烧钱”的过程，这样一款在商业上成功的游戏，也势必会有资本涌进高规格精品游戏的制作中，许多在过去胎死腹中的游戏甚至会有机会重新启航 就如同直到今天还不断涌现的各种类完蛋的恋爱FMV游戏，希望国产游戏的春天也能伴随着这股春风早日到来 | I2: 《黑神话:悟空》对我们这代长年接触单机游戏，但往往只有欧美和日厂游戏可玩的玩家而言，真可谓是一剂强心剂。尽管近些年来优秀的国产独立游戏层出不穷，其中不乏同样能体现中华文化的佳作，但国人心中始终心怀一个梦想，“要有国产3A游戏就好了”。可能单从游戏性上规格体量高的游戏也并不能说明什么，但这却的的确确是游戏工业化的一大标签，对于突破国界向世界展现文化影响力而言，高规格游戏也有其不可替代性，从没有一个国家的玩家会整日将如“3A游戏”的词汇挂在嘴边，足可见他们的渴望。就在这如同荒漠渴望雨水时，2020年8月20日，大圣踩着筋斗云出现了 四年之约终有期 我第一次看见游戏PV时还是在大学时期，大圣变为一只金蝉进入黑风山，在就像是人参成精的土地公公指引下，进入观音禅院挑战被玩家戏称为“毛多弱火”的灵虚子。这一段预告相当激励人心，和国外一线大作肉眼几乎看不出明显差距的超强画面表现力，让无数国人玩家深藏在心中的梦想悄然间长出萌芽。毕竟相较于国外的蝙蝠侠、蜘蛛侠、美国队长等诸多有着超能力的硬汉，齐天大圣才一直是我们孩童时期的幻想，属于我们自己的超级英雄！而在高规格的游戏画面里耳边响起经典的“云宫迅音”，眼前是大圣的金箍棒，我至今难以忘记当初随着音乐鼓点颤动的心跳 但PV毕竟只是PV，我虽然在之后的每次观看黑神话预告时都还是会“焚香沐浴”一番，戴上耳机端坐在电脑前，而不会只是在手机小屏幕上观看，但在黑神话这四年时间的前后，数个尽管影响力没有这般大但同样相对高规格的国产游戏，或上线后褒贬不一、有限销量然后道歉下架绝版喜加一，要么干脆的胎死腹中，网上留存的也仅有一些片段。从以前的国产EA阶段游戏不可信、到现在的高规格游戏个个难产，让其声誉降至谷底，导致我其实对《黑神话:悟空》也难提起更多信心，说到底，这毕竟只是游戏科学团队应对如此体量作品的处女作，一个从未统筹过如此大项目的团队，甚至第一个PV的初衷还更多是因为团队缺人的缘故，面对如此这般泼天的流量和关注，是否能静下心来、保持初心的好好做游戏，对此我始终心存疑虑，更惶恐这如果真是一场“诈骗”对目前纤柔的萌芽阶段会是怎样一个毁灭性打击 2024年8月20日，没有跳票的，《黑神话:悟空》如期上线了。其实就在几天前的性能测试工具开放时，我这颗忐忑的心就放下了大半，一个如此有信心，在游戏开售前弄个测试工具事先应对玩家对游戏优化的疑虑，实际测试结果对中低端硬件的明显包容，很难让人不相信，游戏科学团队的确也已做好万全准备。而面对游戏发售前的泄露事件，制作人冯骥老师更是直接坦言道 最后，我依然很有信心，无论你（无意或是被迫）提前看过了多少已经泄露的内容，这个游戏仍然会带给你从未有过的感受与足够独特的乐趣。所以，不必担心，不必懊恼，《黑神话：悟空》没那么脆弱 是的，我相信《黑神话:悟空》没有这么脆弱，我相信这会是款足够好玩的游戏，不用媒体评分，不用看泄露视频，越临近答案揭晓的时刻，我越有信心，我从未如此笃定过 沉醉不知归路 不管是在过去观看预告PV的“云游戏”，还是此次自己的上手体验。《黑神话:悟空》那别具一格的、带有强烈东方元素的高级审美，都令我印象深刻。在如无头苍蝇般瞎转悠的同时，我总是被美好景致所感染的不由自主的停下前进探索的脚步，感受身边的风声蝉鸣、小桥流水和小妖怪的窃窃私语，观察着天边的第一缕阳光穿过大树的翠绿落到蒲团上，身边残破锈迹斑斑的佛陀像的双眼似乎尽显世态炎凉，自然风貌和人文建筑历经沧桑带来同样厚重感的和谐，这都是此前难以在其他国家的游戏作品中感受到的东方风韵，不需任何言语的堆砌，这种文化魅力只需要你站在那里，就会被深深的感染到 不过，在于光影的协调上不知道是不是因为我个人设置的关系，感觉存在一些小瑕疵。忽明忽暗的场景色调变化的较为频繁，不时的出现一些场景要么昏暗到影响探索，只能依赖于什么时候撞到空气墙然后亦步亦趋的继续，要么离开昏暗场景时瞬时的光暗反差表现过于明显到甚至有点晃眼。不少玩家认为这很有些“现实感”，我姑且认为这是调侃，毕竟这在美术表现如此高格调时所出现的一点点不良体验都足够明显 也正因为如此，《黑神话:悟空》也是我认为的相当适合如《刺客信条:起源》和《刺客信条:奥德赛》做个如“探索之旅”般，玩家只需要当个步行模拟器游玩的模式的游戏。并且，在游戏破圈后势必会有大量此前从未接触过ARPG游戏的轻度玩家，虽然并非说《黑神话:悟空》只有什么硬核高玩才能玩的下去，只是说，对于那部分可能对自己没什么信心，只是单纯想购买游戏权做支持的玩家而言，引入这样的探索模式对于他们来说，是个门槛几近于无的同时，能通过电子游戏感受这一份东方美学和文化浸染的好机会。而对于我们国家当前这个市场，尽可能多的加深游戏“文化赋分”的内容，强化更多正向的帽子，也不失为是件可以摆在台面上大肆宣传的好事 看我棍棒之下无一合之敌！ 此部分想从ARPG游戏的ACT和RPG两部分稍微展开来说一下 不得不承认，在同类游戏如此多的情况下，作为后来者《黑神话:悟空》的战斗系统还是做的很有特色。玩家主要需要通过轻重攻击来打伤害，轻攻击积累棍势，重攻击蓄力和切手技消耗棍势。除了初始的更适合追击敌人的劈棍式，还有可以将棍子撑长伫在原地然后狠狠下劈的立棍式和站在原地用长棍狠戳对面的戳棍式，三种不同的棍法也有着各自不同的延伸可供加点成长的技能点，从而产生不同的应对策略和派生流派 此外，还有诸如定身术的法术深化了悟空特色的战斗方式，随流程推进逐步解锁的诸般新法术新能力鼓励玩家尝试不同的方式战胜强敌。类同大圣七十二般变化的变身系统更让战斗的花样性有着很强的提升，虽然我个人操作有限更多时候都只能将变身期间当做肉盾扛血的休息间隙，但哪怕是最初的刀郎教头广智许多玩家也能利用好变身期间一下子打空boss们大半管血 至于和变化相似的“精魄”，玩家可以在打败精英小BOSS后，用葫芦吸收其精魄，然后在战斗中可以使出它们经典招式的一击。但老实说，我觉得“精魄”在自成体系的战斗系统中显得有些冗余，在对战中由于CD过长且作用着实有限，“精魄”的存在感属实不高，倒是在某些场合的功能性更为突出，比如可以用幽魂的捶地一击打破墙壁。不得不怀疑起初游科想的是将这些统统归到七十二变的变化中，或是工作量过大的缘故，其中的大部分变化被简化成“精魄”，让此多少显得有些格格不入 至于ARPG中的养成部分，其实《黑神话：悟空》这方面的内容较为常规，数值变化除了等级提升外的加点，更多的是通过装备属性上的加成，但装备属性的选择实则并不太自由，随阶段逐步解锁升级的装备让不同玩家之间的选择差异性也较为有限，而在某些阶段过快的装备套装更迭速度，让有些时候玩家容易产生“之前花了资源升级的某套装备好浪费，数值没提升多少不如留着升这套”的不良情绪 在BOSS Rush的路上处处碰“壁” 《黑神话：悟空》在关卡式分章节体的多张地图里塞满了各种的BOSS，按照其他玩家所说数量高达81只对应西行路上的九九八十一难，极度的堆量程度浪费到在只要不迷路的情况下往往走上几步路就要面对一只全新机制、此前从未接触过的新BOSS，更别提每一只BOSS所对应的各式场景和华丽演出，虽然有些时候因为尚未摸清套路显得有些受苦，但操控着“天命人”全情投入克服此前自以为难以逾越的困难，也自会产生成就感并更有勇气面对接下来遇到的其他“难” 战斗，爽！ 在BOSS战时视角的智能锁定成为一个问题，我因为时间有限攻略的内容不太多，关于视角问题印象很深的是在第一章关底，挑战黑熊精时，因为其庞大的体型，我在多数锁定视角下仅仅能看得到黑熊精的脚和满屏幕的黑毛，这也就导致在躲避伤害时我只能凭借此前黑熊精的攻击间隔猜测——它的下一招该出招了，或许我该躲了 而这也不仅仅是面对体型巨大的敌人会存在的视角问题，种类数量如此庞大的BOSS们，有龙跃于天的，有快速移动的，如果视角不是足够的智能，那对玩家的战斗体验多多少少会存在一些影响 在塞满BOSS的西行路上，很大一部分的BOSS并不是在主线道路上，玩家往往需要完成各种隐藏内容才能解锁，许多玩家一周目初见不看攻略通关后会赫然发现，许多的BOSS甚至都没有见到过 在大量隐藏内容之下，游戏关卡内分布较为密集的空气墙对玩家的探索造成了较负面的影响。《黑神话：悟空》并非是款开放世界的游戏，有空气墙倒逼玩家往设计好的道路上探索这无可厚非，但在一些看起来明显能走的道路上，却布好空气墙阻碍玩家前进，当这样的经历多次出现，很难说玩家能提起足够的心气在地图上尽情探索，寻找潜藏着隐藏内容。过分的限制玩家探索和塞满隐藏内容之间，这本就存在矛盾 在逼迫玩家“不撞南墙不回头”时，游戏的许多场景也缺失了必要的指引，有且仅有在附近有土地庙时我观察到在指引上有着些许设计。我丝毫不怀疑许多方向感比较强的“天命人”对此感觉毫无障碍，但对我这般麋鹿选手，在没有地图和适时指引且周边场景无明显地标之下，玩了一小时走回到了初遇的土地庙也并不新奇 重走西行路，再临九九八十一难 作为一部《西游记》后传作品，《黑神话：悟空》保持着严肃的改编风格，对自己理解的《西游记》做出了自己合乎逻辑自洽的注解，这让游戏并非只是成为一款简单的“Boss Rush”游戏，每一句台词，甚至于每一种小妖的图鉴都值得玩家细细揣摩，通过对原著的极致理解，通过大量自己的刻画，通过寥寥数笔描绘出了数个经典人物，并适时的引入包括“天命人”在内的全新设定却不显违和，就好像故事天然的就应该这么走下去 其实，设身处地的想，如果我是一名外国人，玩到《黑神话：悟空》这样的游戏，虽然依旧觉得好玩，但由于缺乏了那股子土生土长的文化浸染力，在游戏内容设计之外处处透着难以理解的排斥感，恐怕这也只是会成为我生命中一过客的游戏，和其他的动作游戏并没有太大的不同 但站在现下的这个时代背景下，国内单机游戏市场称之为荒漠虽然有些夸张但还是挺有现实性的，此时出现了一款游戏，将中国人耳熟能详的故事搬进每个玩家的荧幕前，熟悉的角色操着地道的口音，一进游戏默认的中文字幕中文配音，而老外却要苦恼有时候莫名出现BUG英文配音丢失 从想玩游戏没地方玩到处找资源，到找到资源了苦等汉化组出汉化。从终于有许多游戏玩了但都是海外游戏，到今天的国产游戏也证明了它不是丝毫没有可取之处。这条路我们走的好累，但终于见到了荒漠中的翠绿萌芽。《黑神话：悟空》于国人玩家而言远不是一款游戏这么简单，在移动端收益已进入下降趋势，手游的研发、发行、运营也变成一个“卷”且“烧钱”的过程，这样一款在商业上成功的游戏，也势必会有资本涌进高规格精品游戏的制作中，许多在过去胎死腹中的游戏甚至会有机会重新启航 就如同直到今天还不断涌现的各种类完蛋的恋爱FMV游戏，希望国产游戏的春天也能伴随着这股春风早日到来 | J2: =IF(SUM(R2:T2)>0,1,0) -> 1 | K2: =IF(SUM(U2:Y2)>0,1,0) -> 1 | L2: =IF(SUM(Z2:AC2)>0,1,0) -> 1 | M2: =IF(SUM(AD2:AF2)>0,1,0) -> 1 | N2: =IF(SUM(AG2:AH2)>0,1,0) -> 1 | O2: =IF(SUM(AI2:AL2)>0,1,0) -> 1 | P2: =IF(SUM(AM2:AQ2)>0,1,0) -> 1 | Q2: =IF(AR2>0,1,0) -> 1 | R2: 1 | S2: 1 | T2: 1 | U2: 1 | V2: 1 | W2: 1 | X2: 1 | Y2: 1 | Z2: 1 | AA2: 1 | AB2: 1 | AC2: 1 | AD2: 1 | AE2: 0 | AF2: 1 | AG2: 1 | AH2: 1 | AI2: 1 | AJ2: 0 | AK2: 0 | AL2: 1 | AM2: 0 | AN2: 0 | AO2: 0 | AP2: 1 | AQ2: 1 | AR2: 1 | AS2: =SUM(J2:Q2) -> 8 | AT2: =SUM(R2:AR2) -> 21 | AU2: 画面美术场景；音乐音效配音；演出角色怪物设计；动作打击手感；Boss战斗节奏；难度挑战；锁定视角；判定反馈；地图路线；空气墙可达性；探索隐藏支线；引导迷路单线；优化帧率；Bug兼容硬件；整体完成度；推荐价值判断；西游悟空符号；中国文化宗教语言审美；外部资料依赖；角色期待意义偏移；国产3A身份期待 | AV2: =IF(AT2>0,1,0) -> 1 | AW2: =IF(AT2=0,1,0) -> 0 | AX2: =IF(AT2>=8,1,0) -> 1 | AY2: 189.5 | AZ2: 正面 | BA2: P | BB2: 原文
A3: CN-P-002 | B3: 中文 | C3: 推荐 | D3: 353 | E3: 11 | F3: 88.3 | G3: 2024-08-20 | H3: 历时两月，终得八十一难圆满，欢喜之余写下本测评。 还记得2020年8月20号，黑神话第一个PV横空出世的日子；对那时的我而言不过是平静且普通的一天。我在公司座位上摸鱼，数着时间等下班吃饭。突然游戏群里转了一个视频，转发人无比激动大呼牛逼。 我粗略一看标题：“...悟空...实机演示...”。嗨呀，估计又是个以西游记为噱头骗投资的玩意儿。看到大圣归来骗了那么多经费，也想学一学？ 虽说有些嗤之以鼻，但我还是点开了视频。 嗯？这个配音？嗯？这种品质的画面？？纯实机演示？真的假的？这个制作水平，真的是国内游戏公司能做出来的？ 我惊讶欣喜，紧接着，《如意金箍棒》五个大字一出，我心中一震。随后，雷音寺、紧箍咒、四大天王、筋斗云、大闹天宫等耳熟能详的元素一一展现，我仿佛又回到了小时候和弟弟挤在电视机前看86版西游记的日子；再接着，唢呐吹奏的云宫迅音如雷贯耳般将我惊醒，我这才发现我的眼眶已经湿润一片。画面结束，我却激动到不能自己，浑身止不住地颤抖，整个人恍若梦中。 那一天我把整个PV重复看了无数遍。人生中少有时刻能激动至此，以至于过了4年，当时的感受仍然历历在目。 后来，我一直在想，黑神话的PV热度如此之高，无疑已经到达破圈的程度。如果黑神话真的按PV的规格做出来了，无疑会给死气沉沉的国产单机带来改变；若发售后销量口碑不差，甚至还会给与市场对于单机蓝海的信心；也许会有更多公司将目光从手游网游转向单机，也许我作为玩家能玩到更多国产游戏？ 同时我也心慌：如果这个游戏到头来只是一场骗局，实际内容真的只有PV展示的内容，甚至大幅缩水，那对国内单机玩家而言肯定是无比沉重的一击，就像血狮、幻那样，劣质游戏一步步将玩家对国内厂商的信任消耗殆尽，最终对国产单机再无期望。 很幸运，游戏科学做到了。他们证明了，国内并不是做不出好游戏，只是没人去做。 同时，我也很高兴，玩家们也证明了，国内并不缺少为单机付费的人，而是缺少值得去付费的游戏。所谓国内单机市场小、玩家都是玩盗版，做单机死路一条的言论，或许在十几年前是对的，但到了如今，全都不攻自破。 祝愿国产单机能越来越好。 | I3: 历时两月，终得八十一难圆满，欢喜之余写下本测评。 还记得2020年8月20号，黑神话第一个PV横空出世的日子；对那时的我而言不过是平静且普通的一天。我在公司座位上摸鱼，数着时间等下班吃饭。突然游戏群里转了一个视频，转发人无比激动大呼牛逼。 我粗略一看标题：“...悟空...实机演示...”。嗨呀，估计又是个以西游记为噱头骗投资的玩意儿。看到大圣归来骗了那么多经费，也想学一学？ 虽说有些嗤之以鼻，但我还是点开了视频。 嗯？这个配音？嗯？这种品质的画面？？纯实机演示？真的假的？这个制作水平，真的是国内游戏公司能做出来的？ 我惊讶欣喜，紧接着，《如意金箍棒》五个大字一出，我心中一震。随后，雷音寺、紧箍咒、四大天王、筋斗云、大闹天宫等耳熟能详的元素一一展现，我仿佛又回到了小时候和弟弟挤在电视机前看86版西游记的日子；再接着，唢呐吹奏的云宫迅音如雷贯耳般将我惊醒，我这才发现我的眼眶已经湿润一片。画面结束，我却激动到不能自己，浑身止不住地颤抖，整个人恍若梦中。 那一天我把整个PV重复看了无数遍。人生中少有时刻能激动至此，以至于过了4年，当时的感受仍然历历在目。 后来，我一直在想，黑神话的PV热度如此之高，无疑已经到达破圈的程度。如果黑神话真的按PV的规格做出来了，无疑会给死气沉沉的国产单机带来改变；若发售后销量口碑不差，甚至还会给与市场对于单机蓝海的信心；也许会有更多公司将目光从手游网游转向单机，也许我作为玩家能玩到更多国产游戏？ 同时我也心慌：如果这个游戏到头来只是一场骗局，实际内容真的只有PV展示的内容，甚至大幅缩水，那对国内单机玩家而言肯定是无比沉重的一击，就像血狮、幻那样，劣质游戏一步步将玩家对国内厂商的信任消耗殆尽，最终对国产单机再无期望。 很幸运，游戏科学做到了。他们证明了，国内并不是做不出好游戏，只是没人去做。 同时，我也很高兴，玩家们也证明了，国内并不缺少为单机付费的人，而是缺少值得去付费的游戏。所谓国内单机市场小、玩家都是玩盗版，做单机死路一条的言论，或许在十几年前是对的，但到了如今，全都不攻自破。 祝愿国产单机能越来越好。 | J3: =IF(SUM(R3:T3)>0,1,0) -> 1 | K3: =IF(SUM(U3:Y3)>0,1,0) -> 1 | L3: =IF(SUM(Z3:AC3)>0,1,0) -> 1 | M3: =IF(SUM(AD3:AF3)>0,1,0) -> 0 | N3: =IF(SUM(AG3:AH3)>0,1,0) -> 1 | O3: =IF(SUM(AI3:AL3)>0,1,0) -> 1 | P3: =IF(SUM(AM3:AQ3)>0,1,0) -> 0 | Q3: =IF(AR3>0,1,0) -> 1 | R3: 1 | S3: 1 | T3: 0 | U3: 1 | V3: 0 | W3: 0 | X3: 0 | Y3: 0 | Z3: 0 | AA3: 0 | AB3: 0 | AC3: 1 | AD3: 0 | AE3: 0 | AF3: 0 | AG3: 1 | AH3: 1 | AI3: 1 | AJ3: 1 | AK3: 0 | AL3: 0 | AM3: 0 | AN3: 0 | AO3: 0 | AP3: 0 | AQ3: 0 | AR3: 1 | AS3: =SUM(J3:Q3) -> 6 | AT3: =SUM(R3:AR3) -> 9 | AU3: 画面美术场景；音乐音效配音；动作打击手感；引导迷路单线；整体完成度；推荐价值判断；西游悟空符号；童年记忆情怀；国产3A身份期待 | AV3: =IF(AT3>0,1,0) -> 1 | AW3: =IF(AT3=0,1,0) -> 0 | AX3: =IF(AT3>=8,1,0) -> 1 | AY3: 10 | AZ3: 正面 | BA3: P | BB3: 原文
A4: CN-P-003 | B4: 中文 | C4: 推荐 | D4: 328 | E4: 13 | F4: 106.6 | G4: 2024-08-20 | H4: 献给中国玩家的一封情书 ： 你曾无数次地在游戏世界里扮演着不同的角色：你曾纵马驰骋在狂野的美国西部，书写一代枭雄落幕前的史诗，最终见证了一位想成为好人or坏人的传奇牛仔—— “亚瑟·摩根 ”以悲剧的形式谢幕；你曾在希腊神话里屠戮众神，完成自己的复仇，挣脱命运的束缚，最终成为新的 “战神”——奎爷，于北欧国度中与儿子续写传奇；你曾扮演一位被称为 “白狼” 的猎魔人，在追寻身负上古之血的养女时沉迷于昆特牌亦或是打桩等活动，与此同时书写着属于“利维亚的杰洛特” 最后的故事；你曾徘徊于历史与现代，在文艺复兴的欧洲见证了一代刺客大师的蜕变，并造就了一代代刺客的薪火相传，只为捍卫属于他们的 “信条” ；你曾甘为 “褪色者” ，在交界地中向众神发起挑战，受尽苦痛，磨练技术，终究如愿成为“艾尔登之王”，开辟了一个新的时代；你曾扮演一位名为 “狼” 的忍者，穿梭于日本战国时代的各个角落，历经战乱与冲突，不断提升自身实力挑战各路奇能异士，只为履行职责——保护主人；你曾以 “勇者林克” 的身份在未知的神殿醒来，跨越整个海拉鲁大陆，凭借自己的创造性与想象力自由地探索，上演了一出拯救公主的经典戏码，诠释了忠诚与勇气的可贵；你也曾为实现那理想中的“美国梦”，自由地在洛圣都中做想做的事，扮演那三个男人闯出了一片天地，最终也毫不犹豫地选择以 “死亡之愿” 谢幕…… （其余请自行补充）在你曾扮演过的这些游戏角色中，你可能拯救了无数个支离破碎的世界，亦或是在许多不同的世界中自由地探索冒险，书写了无数动人心弦的故事，了解了异国他乡的风土人情，感受到了不同国家文化展现的魅力。然而在看着身边的一个个同龄人被国内的一些同质化网游和手游蚕食甚至沉迷于为皮肤氪金时，难免也会不甘地想到：我们什么时候才能做出这样的好游戏啊... 直到2020.8.20这一天，一个名不经传的公司默默地发布了一则预告片，这个带着国风标签的3A大作就此出现在了大众的视野里，重燃起了国单的希望。而四年后的这一天，你终于能够来到这个熟悉而又陌生的世界，扮演一只似曾相识的猴子，亦或是儿时耳熟能详的齐天大圣，书写独属于家乡的故事，在这充满着归属感的4k蓝光超高清修复版的“西游记”里作为一位天命人重新踏上一段熟悉的征程，直面你的天命……现在很多游戏都适配了简中甚至拥有中配了，但我还是想说： 以前是：Language——简体中文 这次是：语言——English！！！ 最后，虽然目前某些所谓的评分争议很大，可能低于很多人的期望（个人而言挺不甘心的）但是在承载了众多国内外玩家以及制作者多年的期盼，甚至已经破圈的前提下，他们已经用行动证明了国单市场是存在的，因此我认为黑神话：悟空不仅已经做到了一款国单玩家心中的3A游戏该有的水平，也让人们有了重温经典的动力，毕竟“踏上取经路，比抵达灵山更重要！”于某些更早一批的玩家而言，这一天不止等了四年，更不是七年，而是四十余年......再于中国文化而言，始于明朝吴承恩的《西游记》原著，于1961年最早的动画电影《大圣归来》开始，到经典的86版的《西游记》，95年星爷的《大话西游》，99的动画片《西游记》，15年国产动画电影回归之作《西游记之大圣归来》，再到如今横空出世的《黑神话：悟空》，大圣从始至终都在引领我们做出改变....所以无论如何，它都是独属于我们国人的浪漫。我希望游科的这群理想主义者在这部白骨之后以七年磨一剑的作品能够大卖，将我们这款中国人自己做的第一款真正意义上的3A大作带向世界。毕竟就目前国内急功近利的游戏环境而言，眼下正是黑神话，也只有黑神话，才能够打破国内外的偏见，重振国单市场，带领中国游戏真正地立足于世界，给国内那些所谓的大厂树立一个真正的榜样，做我们曾不敢做的梦。 事实证明游戏早已不仅仅是娱乐，更不只是圈钱的“电子鸦片”，而是一种能将经典再现的艺术，更是一种文化输出的全新途径。毋庸置疑的是我认为这款游戏已足矣成为中国游戏史上的一块里程碑，它也有资格代表着第九艺术传达我们的文化，为咱们的文化正名。而我也坚信这仅仅是一个开始。 ———愿云宫迅音奏响于世界之巅 接着耍🐒去了 | I4: 献给中国玩家的一封情书 ： 你曾无数次地在游戏世界里扮演着不同的角色：你曾纵马驰骋在狂野的美国西部，书写一代枭雄落幕前的史诗，最终见证了一位想成为好人or坏人的传奇牛仔—— “亚瑟·摩根 ”以悲剧的形式谢幕；你曾在希腊神话里屠戮众神，完成自己的复仇，挣脱命运的束缚，最终成为新的 “战神”——奎爷，于北欧国度中与儿子续写传奇；你曾扮演一位被称为 “白狼” 的猎魔人，在追寻身负上古之血的养女时沉迷于昆特牌亦或是打桩等活动，与此同时书写着属于“利维亚的杰洛特” 最后的故事；你曾徘徊于历史与现代，在文艺复兴的欧洲见证了一代刺客大师的蜕变，并造就了一代代刺客的薪火相传，只为捍卫属于他们的 “信条” ；你曾甘为 “褪色者” ，在交界地中向众神发起挑战，受尽苦痛，磨练技术，终究如愿成为“艾尔登之王”，开辟了一个新的时代；你曾扮演一位名为 “狼” 的忍者，穿梭于日本战国时代的各个角落，历经战乱与冲突，不断提升自身实力挑战各路奇能异士，只为履行职责——保护主人；你曾以 “勇者林克” 的身份在未知的神殿醒来，跨越整个海拉鲁大陆，凭借自己的创造性与想象力自由地探索，上演了一出拯救公主的经典戏码，诠释了忠诚与勇气的可贵；你也曾为实现那理想中的“美国梦”，自由地在洛圣都中做想做的事，扮演那三个男人闯出了一片天地，最终也毫不犹豫地选择以 “死亡之愿” 谢幕…… （其余请自行补充）在你曾扮演过的这些游戏角色中，你可能拯救了无数个支离破碎的世界，亦或是在许多不同的世界中自由地探索冒险，书写了无数动人心弦的故事，了解了异国他乡的风土人情，感受到了不同国家文化展现的魅力。然而在看着身边的一个个同龄人被国内的一些同质化网游和手游蚕食甚至沉迷于为皮肤氪金时，难免也会不甘地想到：我们什么时候才能做出这样的好游戏啊... 直到2020.8.20这一天，一个名不经传的公司默默地发布了一则预告片，这个带着国风标签的3A大作就此出现在了大众的视野里，重燃起了国单的希望。而四年后的这一天，你终于能够来到这个熟悉而又陌生的世界，扮演一只似曾相识的猴子，亦或是儿时耳熟能详的齐天大圣，书写独属于家乡的故事，在这充满着归属感的4k蓝光超高清修复版的“西游记”里作为一位天命人重新踏上一段熟悉的征程，直面你的天命……现在很多游戏都适配了简中甚至拥有中配了，但我还是想说： 以前是：Language——简体中文 这次是：语言——English！！！ 最后，虽然目前某些所谓的评分争议很大，可能低于很多人的期望（个人而言挺不甘心的）但是在承载了众多国内外玩家以及制作者多年的期盼，甚至已经破圈的前提下，他们已经用行动证明了国单市场是存在的，因此我认为黑神话：悟空不仅已经做到了一款国单玩家心中的3A游戏该有的水平，也让人们有了重温经典的动力，毕竟“踏上取经路，比抵达灵山更重要！”于某些更早一批的玩家而言，这一天不止等了四年，更不是七年，而是四十余年......再于中国文化而言，始于明朝吴承恩的《西游记》原著，于1961年最早的动画电影《大圣归来》开始，到经典的86版的《西游记》，95年星爷的《大话西游》，99的动画片《西游记》，15年国产动画电影回归之作《西游记之大圣归来》，再到如今横空出世的《黑神话：悟空》，大圣从始至终都在引领我们做出改变....所以无论如何，它都是独属于我们国人的浪漫。我希望游科的这群理想主义者在这部白骨之后以七年磨一剑的作品能够大卖，将我们这款中国人自己做的第一款真正意义上的3A大作带向世界。毕竟就目前国内急功近利的游戏环境而言，眼下正是黑神话，也只有黑神话，才能够打破国内外的偏见，重振国单市场，带领中国游戏真正地立足于世界，给国内那些所谓的大厂树立一个真正的榜样，做我们曾不敢做的梦。 事实证明游戏早已不仅仅是娱乐，更不只是圈钱的“电子鸦片”，而是一种能将经典再现的艺术，更是一种文化输出的全新途径。毋庸置疑的是我认为这款游戏已足矣成为中国游戏史上的一块里程碑，它也有资格代表着第九艺术传达我们的文化，为咱们的文化正名。而我也坚信这仅仅是一个开始。 ———愿云宫迅音奏响于世界之巅 接着耍🐒去了 | J4: =IF(SUM(R4:T4)>0,1,0) -> 1 | K4: =IF(SUM(U4:Y4)>0,1,0) -> 1 | L4: =IF(SUM(Z4:AC4)>0,1,0) -> 1 | M4: =IF(SUM(AD4:AF4)>0,1,0) -> 0 | N4: =IF(SUM(AG4:AH4)>0,1,0) -> 1 | O4: =IF(SUM(AI4:AL4)>0,1,0) -> 1 | P4: =IF(SUM(AM4:AQ4)>0,1,0) -> 1 | Q4: =IF(AR4>0,1,0) -> 1 | R4: 1 | S4: 1 | T4: 1 | U4: 0 | V4: 0 | W4: 1 | X4: 1 | Y4: 0 | Z4: 0 | AA4: 0 | AB4: 1 | AC4: 0 | AD4: 0 | AE4: 0 | AF4: 0 | AG4: 1 | AH4: 1 | AI4: 1 | AJ4: 1 | AK4: 1 | AL4: 1 | AM4: 0 | AN4: 0 | AO4: 0 | AP4: 0 | AQ4: 1 | AR4: 1 | AS4: =SUM(J4:Q4) -> 7 | AT4: =SUM(R4:AR4) -> 14 | AU4: 画面美术场景；音乐音效配音；演出角色怪物设计；难度挑战；锁定视角；探索隐藏支线；整体完成度；推荐价值判断；西游悟空符号；童年记忆情怀；本国媒介路径；中国文化宗教语言审美；角色期待意义偏移；国产3A身份期待 | AV4: =IF(AT4>0,1,0) -> 1 | AW4: =IF(AT4=0,1,0) -> 0 | AX4: =IF(AT4>=8,1,0) -> 1 | AY4: 68.5 | AZ4: 正面 | BA4: P | BB4: 原文
A5: CN-P-004 | B5: 中文 | C5: 推荐 | D5: 259 | E5: 8 | F5: 71.3 | G5: 2024-08-20 | H5: 四年等待不负期望 依稀记得，2020年8月20日，对于大多数人来说，本是平常的一天，但一款名为《黑神话悟空》的游戏发布了第一支PV实机演示视频。 欢迎关注 网易UU鉴赏家培养计划 关注UU加速器VX公众号，回复“steam”，获得专属玩家群邀请。 经典的说书人旁白，贴近原著高度还原的神通变化，如意金箍棒，定身术和分身术，激战刀郎教头与灵虚子的战斗场景，压迫感十足的四大天王与孙悟空对峙等内容都让国内的玩家沸腾了——首款国产3A游戏，还是以大家耳熟能详的西游记作为背景故事！ 视角回到现在，这段视频已不再是想象的片段，苦等4年，《黑神话悟空》终于发售了！它也没有辜负玩家们的期待，目前我已爆肝打到第六章，游戏质量早已远远超出我的预期，我必须发自真心的说一句《黑神话悟空》牛逼！ 玩法心得 先分享下攻略吧，说实话，目前很多人吹的棍花流其实到了游戏中后期强度真的一般，我来给大家推荐一套比较强力的狂战暴力玩法！ 套装：红孩儿四件套（25增伤，30易伤） 武器：天龙棍（140攻击，9暴率，蓄力引雷上身，攻击附带雷伤害） 饰品：必带两个金纽（满血加攻击一个，仙胞石片（攻击无视抗性） 葫芦：妙仙葫芦＋龙膏（倒马毒钩，双冠血，蜂山石髓，净瓶柳叶） 法宝：绣花针 精魄：疯虎 输出手法：进门吃龙光倍力丸，聚珍伏虎丸（其余药丸可以考虑吃霸体或者棍势积累），之后开禁字法，蓄满等身上落雷。基本大部分BOSS都可以2到4棍子直接敲死。 千秋万代永相颂，七十二变显神通（战斗系统） 作为一款ARPG游戏，本作的战斗体验相当爽快，玩家扮演的“天命人”可以使用类似《仁王》架势的三种棍法，每种棍法都有独特的重攻击以及普攻接重攻的切手技。 劈棍重击可移动自由态蓄力，切手技可GP（看破，弹反）敌人攻击并进行反击，是勇猛激进的棍法。 立棍重击可免疫大部分伤害竖立而上进行蓄力，切手技为大范围扫荡攻击，是适合应对群攻的棍法。 戳棍重击能超远距离攻击并击退敌人，切手技则能够自由拉开与敌人之间的距离，再合适的时机撤步还能触发一些特殊效果，是最灵活多变的棍法。 根据战况不同使用不同的棍法，会有一种兵来将挡,见招拆招的爽快感！ 除了棍法，游戏还有法术，变化，法宝等多种辅助战斗的手段！法术皆还原了原作大圣的神通，例如定住敌人的定身术，拔下一根毫毛召唤出万千分身的分身术！变化则是打败支线BOSS后消耗神力可以化身为这些BOSS，也有独特的精魄技可在短时间内幻化为妖怪形态进行攻击（妖怪技），至于法宝也是原著中各种耳熟能详的法宝，对特定敌人使用特定法宝会有一些意向不到的强力效果。 这些元素结合在一起，形成了一套没有太大上手门槛又充满可玩性的战斗系统 ，唯一的瑕疵是三个棍法普攻模组没有变化，有点小失望。 油锅刀山无所惧，入海遁地破苍穹（关卡及支线设计） 本作采用的是关卡制，每一大关都是一个规模庞大的箱庭小世界。BOSS的数量也突出一个量大管饱，有多达80多个BOSS。此外其中有三分之一是隐藏BOSS，需要玩家通过支线或者探索才能发现他们。许多BOSS还有二阶段同时有着不低的挑战性，各种招式动作也完美还原了原作，可以说本作的BOSS战也是一大亮点。但部分大型BOSS的视角锁定做的有点不尽人意，例如第三章的亢金龙，视角乱飘，攻击很容易落空。部分地图的设计跟指引也存在些许瑕疵，第二关跟第三关好多岔路感觉都不明所以，还有一些看似能走的路结果是空气墙也有点影响玩家的游玩体验。 不过瑕不掩瑜，量大管饱又富有挑战性的BOSS战完全弥补了这些缺点。 长生不死何须恋？不畏神权铁骨铮 （养成系统） 本作在养成方面也不算复杂，没有魂类游戏属性加点，只有个简单易懂的技能树。 大多数技能都能直接提升角色性能跟增加新的动作，当然也有单纯的提升数值的强化，技能随时可在土地庙无代价洗点，最后也能全部点满。（我目前还没通关，不确定高周目能不能全部点满，但我个人感觉应该是能全部点满） 除了技能树，当然少不了装备系统，游戏的装备可以通过各种素材进行打造，每套防具跟武器还有各种特殊的套装效果。打败一些头目时还能获得叫做“玲珑内丹”的道具，交予NPC炼丹后可以永久提升属性上限。 回血道具“葫芦”也能强化自由组合各种效果，使回复机制更加有趣。 关于云存档 本作在Steam平台与WeGame平台均有发售，，两个平台也均有自己的云存档，但是偶尔会遇到云存档上传下载不成功的时候。（特别是福建地区的小伙伴，云存档经常抽风），所以为云存档设置保险还是很有必要的，UU加速器的云存档功能，无论是换电脑玩时存档误覆盖，还是各种问题导致存档损坏。相信这样惨痛的经历依然时常发生，但这次决不能。即便不是会员，也可以免费使用UU云存档功能，全程无需手动，完全自动备份。 并且保留多个档位，面对一些一周目容易错过的支线或者隐藏BOSS，也可以多一个备份，免去二周目烦恼，直接在备份的档位再次选择即可。 另外UU也提供了UU存档市集， C酱、黑桐谷歌等知名主播存档，玩家可以下载下来跟着主播进度玩，多种攻略配合存档，手把手教，包爽！此外还有各种全成就档、全收集档、boss rush档等。总之，你需要的存档，这里都有。 除此之外现在还有抽奖活动，试试自己的手气，说不定就能白嫖游戏直接回本。 结语 顶尖的美术，还原原作各种宏大场景的画面表现，简单易上手又有趣的战斗跟养成系统，量大管饱富有挑战性的BOSS战，《黑神话悟空》是毫无疑问的国产神作！ 甚至对于国内玩家而言，这部作品的意义早已超越了一款普通游戏的范畴，游科现在走的正是一条国内近十几年来“前无古人”的道路——制作一款真正意义上的3A大作！ 希望国内还会有更多有志之士挑起游戏行业的大旗，接过游科的接力棒，将我们国家五千年的深厚文化底蕴展现出去。 | I5: 四年等待不负期望 依稀记得，2020年8月20日，对于大多数人来说，本是平常的一天，但一款名为《黑神话悟空》的游戏发布了第一支PV实机演示视频。 欢迎关注 网易UU鉴赏家培养计划 关注UU加速器VX公众号，回复“steam”，获得专属玩家群邀请。 经典的说书人旁白，贴近原著高度还原的神通变化，如意金箍棒，定身术和分身术，激战刀郎教头与灵虚子的战斗场景，压迫感十足的四大天王与孙悟空对峙等内容都让国内的玩家沸腾了——首款国产3A游戏，还是以大家耳熟能详的西游记作为背景故事！ 视角回到现在，这段视频已不再是想象的片段，苦等4年，《黑神话悟空》终于发售了！它也没有辜负玩家们的期待，目前我已爆肝打到第六章，游戏质量早已远远超出我的预期，我必须发自真心的说一句《黑神话悟空》牛逼！ 玩法心得 先分享下攻略吧，说实话，目前很多人吹的棍花流其实到了游戏中后期强度真的一般，我来给大家推荐一套比较强力的狂战暴力玩法！ 套装：红孩儿四件套（25增伤，30易伤） 武器：天龙棍（140攻击，9暴率，蓄力引雷上身，攻击附带雷伤害） 饰品：必带两个金纽（满血加攻击一个，仙胞石片（攻击无视抗性） 葫芦：妙仙葫芦＋龙膏（倒马毒钩，双冠血，蜂山石髓，净瓶柳叶） 法宝：绣花针 精魄：疯虎 输出手法：进门吃龙光倍力丸，聚珍伏虎丸（其余药丸可以考虑吃霸体或者棍势积累），之后开禁字法，蓄满等身上落雷。基本大部分BOSS都可以2到4棍子直接敲死。 千秋万代永相颂，七十二变显神通（战斗系统） 作为一款ARPG游戏，本作的战斗体验相当爽快，玩家扮演的“天命人”可以使用类似《仁王》架势的三种棍法，每种棍法都有独特的重攻击以及普攻接重攻的切手技。 劈棍重击可移动自由态蓄力，切手技可GP（看破，弹反）敌人攻击并进行反击，是勇猛激进的棍法。 立棍重击可免疫大部分伤害竖立而上进行蓄力，切手技为大范围扫荡攻击，是适合应对群攻的棍法。 戳棍重击能超远距离攻击并击退敌人，切手技则能够自由拉开与敌人之间的距离，再合适的时机撤步还能触发一些特殊效果，是最灵活多变的棍法。 根据战况不同使用不同的棍法，会有一种兵来将挡,见招拆招的爽快感！ 除了棍法，游戏还有法术，变化，法宝等多种辅助战斗的手段！法术皆还原了原作大圣的神通，例如定住敌人的定身术，拔下一根毫毛召唤出万千分身的分身术！变化则是打败支线BOSS后消耗神力可以化身为这些BOSS，也有独特的精魄技可在短时间内幻化为妖怪形态进行攻击（妖怪技），至于法宝也是原著中各种耳熟能详的法宝，对特定敌人使用特定法宝会有一些意向不到的强力效果。 这些元素结合在一起，形成了一套没有太大上手门槛又充满可玩性的战斗系统 ，唯一的瑕疵是三个棍法普攻模组没有变化，有点小失望。 油锅刀山无所惧，入海遁地破苍穹（关卡及支线设计） 本作采用的是关卡制，每一大关都是一个规模庞大的箱庭小世界。BOSS的数量也突出一个量大管饱，有多达80多个BOSS。此外其中有三分之一是隐藏BOSS，需要玩家通过支线或者探索才能发现他们。许多BOSS还有二阶段同时有着不低的挑战性，各种招式动作也完美还原了原作，可以说本作的BOSS战也是一大亮点。但部分大型BOSS的视角锁定做的有点不尽人意，例如第三章的亢金龙，视角乱飘，攻击很容易落空。部分地图的设计跟指引也存在些许瑕疵，第二关跟第三关好多岔路感觉都不明所以，还有一些看似能走的路结果是空气墙也有点影响玩家的游玩体验。 不过瑕不掩瑜，量大管饱又富有挑战性的BOSS战完全弥补了这些缺点。 长生不死何须恋？不畏神权铁骨铮 （养成系统） 本作在养成方面也不算复杂，没有魂类游戏属性加点，只有个简单易懂的技能树。 大多数技能都能直接提升角色性能跟增加新的动作，当然也有单纯的提升数值的强化，技能随时可在土地庙无代价洗点，最后也能全部点满。（我目前还没通关，不确定高周目能不能全部点满，但我个人感觉应该是能全部点满） 除了技能树，当然少不了装备系统，游戏的装备可以通过各种素材进行打造，每套防具跟武器还有各种特殊的套装效果。打败一些头目时还能获得叫做“玲珑内丹”的道具，交予NPC炼丹后可以永久提升属性上限。 回血道具“葫芦”也能强化自由组合各种效果，使回复机制更加有趣。 关于云存档 本作在Steam平台与WeGame平台均有发售，，两个平台也均有自己的云存档，但是偶尔会遇到云存档上传下载不成功的时候。（特别是福建地区的小伙伴，云存档经常抽风），所以为云存档设置保险还是很有必要的，UU加速器的云存档功能，无论是换电脑玩时存档误覆盖，还是各种问题导致存档损坏。相信这样惨痛的经历依然时常发生，但这次决不能。即便不是会员，也可以免费使用UU云存档功能，全程无需手动，完全自动备份。 并且保留多个档位，面对一些一周目容易错过的支线或者隐藏BOSS，也可以多一个备份，免去二周目烦恼，直接在备份的档位再次选择即可。 另外UU也提供了UU存档市集， C酱、黑桐谷歌等知名主播存档，玩家可以下载下来跟着主播进度玩，多种攻略配合存档，手把手教，包爽！此外还有各种全成就档、全收集档、boss rush档等。总之，你需要的存档，这里都有。 除此之外现在还有抽奖活动，试试自己的手气，说不定就能白嫖游戏直接回本。 结语 顶尖的美术，还原原作各种宏大场景的画面表现，简单易上手又有趣的战斗跟养成系统，量大管饱富有挑战性的BOSS战，《黑神话悟空》是毫无疑问的国产神作！ 甚至对于国内玩家而言，这部作品的意义早已超越了一款普通游戏的范畴，游科现在走的正是一条国内近十几年来“前无古人”的道路——制作一款真正意义上的3A大作！ 希望国内还会有更多有志之士挑起游戏行业的大旗，接过游科的接力棒，将我们国家五千年的深厚文化底蕴展现出去。 | J5: =IF(SUM(R5:T5)>0,1,0) -> 1 | K5: =IF(SUM(U5:Y5)>0,1,0) -> 1 | L5: =IF(SUM(Z5:AC5)>0,1,0) -> 1 | M5: =IF(SUM(AD5:AF5)>0,1,0) -> 1 | N5: =IF(SUM(AG5:AH5)>0,1,0) -> 1 | O5: =IF(SUM(AI5:AL5)>0,1,0) -> 1 | P5: =IF(SUM(AM5:AQ5)>0,1,0) -> 1 | Q5: =IF(AR5>0,1,0) -> 1 | R5: 1 | S5: 0 | T5: 0 | U5: 1 | V5: 1 | W5: 1 | X5: 1 | Y5: 0 | Z5: 1 | AA5: 1 | AB5: 1 | AC5: 1 | AD5: 1 | AE5: 0 | AF5: 0 | AG5: 1 | AH5: 1 | AI5: 1 | AJ5: 0 | AK5: 0 | AL5: 1 | AM5: 0 | AN5: 0 | AO5: 0 | AP5: 1 | AQ5: 0 | AR5: 1 | AS5: =SUM(J5:Q5) -> 8 | AT5: =SUM(R5:AR5) -> 16 | AU5: 画面美术场景；动作打击手感；Boss战斗节奏；难度挑战；锁定视角；地图路线；空气墙可达性；探索隐藏支线；引导迷路单线；优化帧率；整体完成度；推荐价值判断；西游悟空符号；中国文化宗教语言审美；外部资料依赖；国产3A身份期待 | AV5: =IF(AT5>0,1,0) -> 1 | AW5: =IF(AT5=0,1,0) -> 0 | AX5: =IF(AT5>=8,1,0) -> 1 | AY5: 81.5 | AZ5: 正面 | BA5: P | BB5: 原文
A6: CN-P-005 | B6: 中文 | C6: 推荐 | D6: 48 | E6: 1 | F6: 128.4 | G6: 2024-08-20 | H6: 53小时，一周目完成，可以评测了。《黑神话：悟空》第九艺术，实至名归，美术之精良，音乐之精美，打斗之精彩...再多的溢美之词其实都不能表达它带给我的震撼。我从没有在其他游戏中如此频繁地打开拍照模式，部分关卡的美术资源真的是铺张到“令人发指”的地步。部分Boss设计如毒敌大王、大圣残躯、虎先锋、亢金龙...着实让人印象深刻，大开大合、见招拆招是真的做出了中式武侠过招的感觉，有的Boss真的算比较难的，但与魂类不同，这些Boss对我而言不会给人一种“我完全过不了”的坐牢感觉，很多时候都是感觉“差一点，应该马上就过了”。即使失误挨打，被一套带走，也会不由叹一句“这Boss设计好酷”。诚然，作为中国玩家，从2020年8月20日开始，我就带着各种光环来看待这个游戏，但是即使抛开国产、西游、第一部3A...在4年之后的今天，它依然是一款足够出色的游戏，一款足够“好玩”的游戏，一款足够“用心”的游戏，更是一款足够“有深度”的游戏。即使夸赞这么多，也不能说它就是“完美”的，相反，关卡设计，引导，还是体现出了不可忽视的短板，这类问题导致的割裂感，在第五、六章节极为明显。同时，与巨大体型Boss的战斗交互，也是需要加强的。这类需要靠经验积累的能力，还是稍显稚嫩，但也显得真实，毕竟这真的是中国3A单机市场的第一作，这种“不完美”，已经比我预想的好了太多。求其上者，得其中。能在全球范围内取得如今的口碑，我其实可以隐约感受到它在开发过程中所耗费的心血与煎熬。在国内，单机游戏这条路，依然是艰难的。但，这个世界需要“务实的理想主义者”，踏上西行之旅，比抵达灵山，更重要。感谢"游戏科学"带来的这场西游大梦，也希望更多的“游戏科学”拓宽这条刚开辟的小路，一步步百花齐放，给全球玩家带来更多的感动。 | I6: 53小时，一周目完成，可以评测了。《黑神话：悟空》第九艺术，实至名归，美术之精良，音乐之精美，打斗之精彩...再多的溢美之词其实都不能表达它带给我的震撼。我从没有在其他游戏中如此频繁地打开拍照模式，部分关卡的美术资源真的是铺张到“令人发指”的地步。部分Boss设计如毒敌大王、大圣残躯、虎先锋、亢金龙...着实让人印象深刻，大开大合、见招拆招是真的做出了中式武侠过招的感觉，有的Boss真的算比较难的，但与魂类不同，这些Boss对我而言不会给人一种“我完全过不了”的坐牢感觉，很多时候都是感觉“差一点，应该马上就过了”。即使失误挨打，被一套带走，也会不由叹一句“这Boss设计好酷”。诚然，作为中国玩家，从2020年8月20日开始，我就带着各种光环来看待这个游戏，但是即使抛开国产、西游、第一部3A...在4年之后的今天，它依然是一款足够出色的游戏，一款足够“好玩”的游戏，一款足够“用心”的游戏，更是一款足够“有深度”的游戏。即使夸赞这么多，也不能说它就是“完美”的，相反，关卡设计，引导，还是体现出了不可忽视的短板，这类问题导致的割裂感，在第五、六章节极为明显。同时，与巨大体型Boss的战斗交互，也是需要加强的。这类需要靠经验积累的能力，还是稍显稚嫩，但也显得真实，毕竟这真的是中国3A单机市场的第一作，这种“不完美”，已经比我预想的好了太多。求其上者，得其中。能在全球范围内取得如今的口碑，我其实可以隐约感受到它在开发过程中所耗费的心血与煎熬。在国内，单机游戏这条路，依然是艰难的。但，这个世界需要“务实的理想主义者”，踏上西行之旅，比抵达灵山，更重要。感谢"游戏科学"带来的这场西游大梦，也希望更多的“游戏科学”拓宽这条刚开辟的小路，一步步百花齐放，给全球玩家带来更多的感动。 | J6: =IF(SUM(R6:T6)>0,1,0) -> 1 | K6: =IF(SUM(U6:Y6)>0,1,0) -> 1 | L6: =IF(SUM(Z6:AC6)>0,1,0) -> 1 | M6: =IF(SUM(AD6:AF6)>0,1,0) -> 0 | N6: =IF(SUM(AG6:AH6)>0,1,0) -> 1 | O6: =IF(SUM(AI6:AL6)>0,1,0) -> 1 | P6: =IF(SUM(AM6:AQ6)>0,1,0) -> 0 | Q6: =IF(AR6>0,1,0) -> 1 | R6: 1 | S6: 1 | T6: 0 | U6: 0 | V6: 1 | W6: 0 | X6: 0 | Y6: 0 | Z6: 1 | AA6: 0 | AB6: 0 | AC6: 1 | AD6: 0 | AE6: 0 | AF6: 0 | AG6: 1 | AH6: 1 | AI6: 1 | AJ6: 0 | AK6: 0 | AL6: 0 | AM6: 0 | AN6: 0 | AO6: 0 | AP6: 0 | AQ6: 0 | AR6: 1 | AS6: =SUM(J6:Q6) -> 6 | AT6: =SUM(R6:AR6) -> 9 | AU6: 画面美术场景；音乐音效配音；Boss战斗节奏；地图路线；引导迷路单线；整体完成度；推荐价值判断；西游悟空符号；国产3A身份期待 | AV6: =IF(AT6>0,1,0) -> 1 | AW6: =IF(AT6=0,1,0) -> 0 | AX6: =IF(AT6>=8,1,0) -> 1 | AY6: 43 | AZ6: 正面 | BA6: P | BB6: 原文
A7: CN-P-006 | B7: 中文 | C7: 推荐 | D7: 51 | E7: 1 | F7: 20.1 | G7: 2024-08-20 | H7: 为了纪念这个游戏转眼间到了发售的日子，就让我想到了一个在这游戏发布的前前三天，正好是我一个朋友的生日。在2021年8月17日的时候，他说真希望能在我下一个生日之前发售，真希望能早点玩到国产魂类的3A游戏。因为2020年8月20日，游戏发布公布首段实机演示视频，拉满了他的期待。在2022年8月17日的时候，他说游戏用上新的引擎，也公示了更多信息，应该不久就要发售了吧。因为2021年8月20日开发团队再次释出一支12分钟的演示预告，由虚幻引擎5实机录制。在2023年8月17日的时候，我想他会说希望剧情能好一点，不要砸了这个招牌就好了。因为2022年8月20日，开发团队发布一支6分20秒剧情短片。在2023年8月17日的时候，我想他一定会带着我去杭州。因为2023年8月20日在杭州举办线下试玩会，体验内容包括多个首领挑战以及独立的关卡片段。时间一转而过就是五年，就想人们常说的，“你永远都不知道意外和明天到底哪一个会先来临”。可是到了游戏发售的日子，他却什么也说不了了。在去年迈入春天的时候，他却倒在了医院惨白的病床上，我当时就在一旁看着他的监护器的波纹逐渐趋近于水平，当什么都化为0的时候，我就知道和我随行那么多年的人，和我玩了那么久游戏的人，却还没能看到他期待的游戏上架就先离去。在2021年的时候，他检测出肺癌晚期，当时不相信自己长期不停的咳嗽居然是肺癌的症状。在2022年的时候，他辗转于医院的各个科室，会诊各个名医，只为了延续他的生命。在2023年的冬天，他给我看了他的病例报告单，上面写了19项病症，他说看到这么多癌转移，还有什么治疗的机会。于是他做了一个决定，他要把自己捐献给医学事业，当时我很震惊也很感动，我想他做了他能做的了吧。他很普通，也很平凡，但是在最后的那一刻，他得到了他主治医生的尊重。人生就是一场很大的舞台戏，如映画一般飘闪而过，并且不能用SL大法，无伤全成就。从认识他到现在，已经过去了十几年了，他走过那么多挫折和磨难，就像过九九八十一难一样，一个一个的度过，直到自己生命的尽头。我想也许他这个样子，就像孙猴子一样，上蹿下跳，总是在不断地折腾，最后也能在西天成为斗战胜佛…… | I7: 为了纪念这个游戏转眼间到了发售的日子，就让我想到了一个在这游戏发布的前前三天，正好是我一个朋友的生日。在2021年8月17日的时候，他说真希望能在我下一个生日之前发售，真希望能早点玩到国产魂类的3A游戏。因为2020年8月20日，游戏发布公布首段实机演示视频，拉满了他的期待。在2022年8月17日的时候，他说游戏用上新的引擎，也公示了更多信息，应该不久就要发售了吧。因为2021年8月20日开发团队再次释出一支12分钟的演示预告，由虚幻引擎5实机录制。在2023年8月17日的时候，我想他会说希望剧情能好一点，不要砸了这个招牌就好了。因为2022年8月20日，开发团队发布一支6分20秒剧情短片。在2023年8月17日的时候，我想他一定会带着我去杭州。因为2023年8月20日在杭州举办线下试玩会，体验内容包括多个首领挑战以及独立的关卡片段。时间一转而过就是五年，就想人们常说的，“你永远都不知道意外和明天到底哪一个会先来临”。可是到了游戏发售的日子，他却什么也说不了了。在去年迈入春天的时候，他却倒在了医院惨白的病床上，我当时就在一旁看着他的监护器的波纹逐渐趋近于水平，当什么都化为0的时候，我就知道和我随行那么多年的人，和我玩了那么久游戏的人，却还没能看到他期待的游戏上架就先离去。在2021年的时候，他检测出肺癌晚期，当时不相信自己长期不停的咳嗽居然是肺癌的症状。在2022年的时候，他辗转于医院的各个科室，会诊各个名医，只为了延续他的生命。在2023年的冬天，他给我看了他的病例报告单，上面写了19项病症，他说看到这么多癌转移，还有什么治疗的机会。于是他做了一个决定，他要把自己捐献给医学事业，当时我很震惊也很感动，我想他做了他能做的了吧。他很普通，也很平凡，但是在最后的那一刻，他得到了他主治医生的尊重。人生就是一场很大的舞台戏，如映画一般飘闪而过，并且不能用SL大法，无伤全成就。从认识他到现在，已经过去了十几年了，他走过那么多挫折和磨难，就像过九九八十一难一样，一个一个的度过，直到自己生命的尽头。我想也许他这个样子，就像孙猴子一样，上蹿下跳，总是在不断地折腾，最后也能在西天成为斗战胜佛…… | J7: =IF(SUM(R7:T7)>0,1,0) -> 0 | K7: =IF(SUM(U7:Y7)>0,1,0) -> 1 | L7: =IF(SUM(Z7:AC7)>0,1,0) -> 1 | M7: =IF(SUM(AD7:AF7)>0,1,0) -> 0 | N7: =IF(SUM(AG7:AH7)>0,1,0) -> 1 | O7: =IF(SUM(AI7:AL7)>0,1,0) -> 0 | P7: =IF(SUM(AM7:AQ7)>0,1,0) -> 0 | Q7: =IF(AR7>0,1,0) -> 1 | R7: 0 | S7: 0 | T7: 0 | U7: 0 | V7: 1 | W7: 1 | X7: 0 | Y7: 0 | Z7: 1 | AA7: 0 | AB7: 0 | AC7: 0 | AD7: 0 | AE7: 0 | AF7: 0 | AG7: 1 | AH7: 0 | AI7: 0 | AJ7: 0 | AK7: 0 | AL7: 0 | AM7: 0 | AN7: 0 | AO7: 0 | AP7: 0 | AQ7: 0 | AR7: 1 | AS7: =SUM(J7:Q7) -> 4 | AT7: =SUM(R7:AR7) -> 5 | AU7: Boss战斗节奏；难度挑战；地图路线；整体完成度；国产3A身份期待 | AV7: =IF(AT7>0,1,0) -> 1 | AW7: =IF(AT7=0,1,0) -> 0 | AX7: =IF(AT7>=8,1,0) -> 0 | AY7: 19.5 | AZ7: 正面 | BA7: P | BB7: 原文
A8: CN-P-007 | B8: 中文 | C8: 推荐 | D8: 20171 | E8: 545 | F8: 51.1 | G8: 2024-08-20 | H8: 一从大地起风雷，便有精生白骨堆。僧是愚氓犹可训，妖为鬼蜮必成灾。金猴奋起千钧棒，玉宇澄清万里埃。今日欢呼孙大圣，只缘妖雾又重来。 | I8: 一从大地起风雷，便有精生白骨堆。僧是愚氓犹可训，妖为鬼蜮必成灾。金猴奋起千钧棒，玉宇澄清万里埃。今日欢呼孙大圣，只缘妖雾又重来。 | J8: =IF(SUM(R8:T8)>0,1,0) -> 0 | K8: =IF(SUM(U8:Y8)>0,1,0) -> 0 | L8: =IF(SUM(Z8:AC8)>0,1,0) -> 0 | M8: =IF(SUM(AD8:AF8)>0,1,0) -> 0 | N8: =IF(SUM(AG8:AH8)>0,1,0) -> 0 | O8: =IF(SUM(AI8:AL8)>0,1,0) -> 1 | P8: =IF(SUM(AM8:AQ8)>0,1,0) -> 0 | Q8: =IF(AR8>0,1,0) -> 0 | R8: 0 | S8: 0 | T8: 0 | U8: 0 | V8: 0 | W8: 0 | X8: 0 | Y8: 0 | Z8: 0 | AA8: 0 | AB8: 0 | AC8: 0 | AD8: 0 | AE8: 0 | AF8: 0 | AG8: 0 | AH8: 0 | AI8: 1 | AJ8: 0 | AK8: 0 | AL8: 0 | AM8: 0 | AN8: 0 | AO8: 0 | AP8: 0 | AQ8: 0 | AR8: 0 | AS8: =SUM(J8:Q8) -> 1 | AT8: =SUM(R8:AR8) -> 1 | AU8: 西游悟空符号 | AV8: =IF(AT8>0,1,0) -> 1 | AW8: =IF(AT8=0,1,0) -> 0 | AX8: =IF(AT8>=8,1,0) -> 0 | AY8: 3 | AZ8: 正面 | BA8: P | BB8: 原文
A9: CN-P-008 | B9: 中文 | C9: 推荐 | D9: 19160 | E9: 8780 | F9: 52.3 | G9: 2024-08-20 | H9: 开服前：最多3天必定拿下杨戬开服打完第1个小boss：今天先拿下虎先锋吧开服后4小时：兄弟们 有没有会打大头的教一下 | I9: 开服前：最多3天必定拿下杨戬开服打完第1个小boss：今天先拿下虎先锋吧开服后4小时：兄弟们 有没有会打大头的教一下 | J9: =IF(SUM(R9:T9)>0,1,0) -> 0 | K9: =IF(SUM(U9:Y9)>0,1,0) -> 1 | L9: =IF(SUM(Z9:AC9)>0,1,0) -> 0 | M9: =IF(SUM(AD9:AF9)>0,1,0) -> 0 | N9: =IF(SUM(AG9:AH9)>0,1,0) -> 0 | O9: =IF(SUM(AI9:AL9)>0,1,0) -> 1 | P9: =IF(SUM(AM9:AQ9)>0,1,0) -> 0 | Q9: =IF(AR9>0,1,0) -> 0 | R9: 0 | S9: 0 | T9: 0 | U9: 0 | V9: 1 | W9: 0 | X9: 0 | Y9: 0 | Z9: 0 | AA9: 0 | AB9: 0 | AC9: 0 | AD9: 0 | AE9: 0 | AF9: 0 | AG9: 0 | AH9: 0 | AI9: 1 | AJ9: 0 | AK9: 0 | AL9: 0 | AM9: 0 | AN9: 0 | AO9: 0 | AP9: 0 | AQ9: 0 | AR9: 0 | AS9: =SUM(J9:Q9) -> 2 | AT9: =SUM(R9:AR9) -> 2 | AU9: Boss战斗节奏；西游悟空符号 | AV9: =IF(AT9>0,1,0) -> 1 | AW9: =IF(AT9=0,1,0) -> 0 | AX9: =IF(AT9>=8,1,0) -> 0 | AY9: 2 | AZ9: 正面 | BA9: P | BB9: 原文
A10: CN-P-009 | B10: 中文 | C10: 推荐 | D10: 12177 | E10: 250 | F10: 162.1 | G10: 2024-08-20 | H10: 回想四年前的今天，如同梦一场。扮演龙裔、猎魔人、刺客、勇者等等都很好，但你说可以当猴哥？这种来自血脉、历史、文化和童年记忆的加成，是过去多少年都不敢想象的。感谢游戏科学，让这场梦成真。全成就之后补充评测，画面、音乐、战斗都很棒，剧情有好有坏也还可以，整个游戏玩完我觉得挺开心，我喜欢玩，而且还要推荐别人玩。游戏看自己喜好，为啥要把自己的观点强加到别人身上，自己喜欢不喜欢友好评价就好，为何要跑到别人的评测下面刷自己怎么怎么破防，甚至破口大骂，和我有啥关系，这游戏又不是我做的。 | I10: 回想四年前的今天，如同梦一场。扮演龙裔、猎魔人、刺客、勇者等等都很好，但你说可以当猴哥？这种来自血脉、历史、文化和童年记忆的加成，是过去多少年都不敢想象的。感谢游戏科学，让这场梦成真。全成就之后补充评测，画面、音乐、战斗都很棒，剧情有好有坏也还可以，整个游戏玩完我觉得挺开心，我喜欢玩，而且还要推荐别人玩。游戏看自己喜好，为啥要把自己的观点强加到别人身上，自己喜欢不喜欢友好评价就好，为何要跑到别人的评测下面刷自己怎么怎么破防，甚至破口大骂，和我有啥关系，这游戏又不是我做的。 | J10: =IF(SUM(R10:T10)>0,1,0) -> 1 | K10: =IF(SUM(U10:Y10)>0,1,0) -> 1 | L10: =IF(SUM(Z10:AC10)>0,1,0) -> 0 | M10: =IF(SUM(AD10:AF10)>0,1,0) -> 0 | N10: =IF(SUM(AG10:AH10)>0,1,0) -> 1 | O10: =IF(SUM(AI10:AL10)>0,1,0) -> 1 | P10: =IF(SUM(AM10:AQ10)>0,1,0) -> 0 | Q10: =IF(AR10>0,1,0) -> 1 | R10: 1 | S10: 1 | T10: 0 | U10: 0 | V10: 1 | W10: 0 | X10: 0 | Y10: 0 | Z10: 0 | AA10: 0 | AB10: 0 | AC10: 0 | AD10: 0 | AE10: 0 | AF10: 0 | AG10: 0 | AH10: 1 | AI10: 1 | AJ10: 1 | AK10: 0 | AL10: 0 | AM10: 0 | AN10: 0 | AO10: 0 | AP10: 0 | AQ10: 0 | AR10: 1 | AS10: =SUM(J10:Q10) -> 5 | AT10: =SUM(R10:AR10) -> 7 | AU10: 画面美术场景；音乐音效配音；Boss战斗节奏；推荐价值判断；西游悟空符号；童年记忆情怀；国产3A身份期待 | AV10: =IF(AT10>0,1,0) -> 1 | AW10: =IF(AT10=0,1,0) -> 0 | AX10: =IF(AT10>=8,1,0) -> 0 | AY10: 10 | AZ10: 正面 | BA10: P | BB10: 原文
A11: CN-P-010 | B11: 中文 | C11: 推荐 | D11: 8886 | E11: 288 | F11: 20.9 | G11: 2024-08-20 | H11: 在正式开始玩之前，为了第一时间体验黑吗喽，今早惊醒了两次，却也迟迟不到开启的时间。最后快到的这半个小时却内心平静，感觉没有一丝波澜。我相信有许多跟我一样的人，第一次看到宣传片过后就热烈地期望着这一游戏，而一次次的实机预告过后又不断提升自己的期望值希望他走得更高更远，希望他能代表着我们国家的中华文化能够走出国门面向世界，告诉世界其他地区的玩家们中国也有一款优秀的中国3A游戏。我还记得第一次预告的时候大家伙讨论的还是黑神话是不是一款3A游戏，逐渐演变到后来他能对标哪款海外3A游戏再到后期的能不能TGA得奖。包括TGA得奖大家也从最开始觉得最佳美术稳了再到最佳音乐有希望再到希望获得年度最佳游戏。马上就要开启的旅程和长期以来的期望让我不希望黑神话会成为那种飞得越高摔得越惨的下场，同时也不希望优质国产游戏的未来落得个虎头蛇尾，伤仲永的结局。不过那些都是未来的事情了，未见未来，混沌与希望共存。到了最后，我由衷地希望黑神话能顺利地走完最后一步，在游玩的旅程当中能达到差强人意的地步就够了，完整地走完九九八十一难中的最后磨难，像流浪地球一样尝试着打开一扇新的通往未来的大门。也祝愿看到这条评论的大家能够玩得开心快乐，回归游戏带给我们快乐的初心。 | I11: 在正式开始玩之前，为了第一时间体验黑吗喽，今早惊醒了两次，却也迟迟不到开启的时间。最后快到的这半个小时却内心平静，感觉没有一丝波澜。我相信有许多跟我一样的人，第一次看到宣传片过后就热烈地期望着这一游戏，而一次次的实机预告过后又不断提升自己的期望值希望他走得更高更远，希望他能代表着我们国家的中华文化能够走出国门面向世界，告诉世界其他地区的玩家们中国也有一款优秀的中国3A游戏。我还记得第一次预告的时候大家伙讨论的还是黑神话是不是一款3A游戏，逐渐演变到后来他能对标哪款海外3A游戏再到后期的能不能TGA得奖。包括TGA得奖大家也从最开始觉得最佳美术稳了再到最佳音乐有希望再到希望获得年度最佳游戏。马上就要开启的旅程和长期以来的期望让我不希望黑神话会成为那种飞得越高摔得越惨的下场，同时也不希望优质国产游戏的未来落得个虎头蛇尾，伤仲永的结局。不过那些都是未来的事情了，未见未来，混沌与希望共存。到了最后，我由衷地希望黑神话能顺利地走完最后一步，在游玩的旅程当中能达到差强人意的地步就够了，完整地走完九九八十一难中的最后磨难，像流浪地球一样尝试着打开一扇新的通往未来的大门。也祝愿看到这条评论的大家能够玩得开心快乐，回归游戏带给我们快乐的初心。 | J11: =IF(SUM(R11:T11)>0,1,0) -> 1 | K11: =IF(SUM(U11:Y11)>0,1,0) -> 0 | L11: =IF(SUM(Z11:AC11)>0,1,0) -> 0 | M11: =IF(SUM(AD11:AF11)>0,1,0) -> 0 | N11: =IF(SUM(AG11:AH11)>0,1,0) -> 0 | O11: =IF(SUM(AI11:AL11)>0,1,0) -> 0 | P11: =IF(SUM(AM11:AQ11)>0,1,0) -> 0 | Q11: =IF(AR11>0,1,0) -> 1 | R11: 1 | S11: 1 | T11: 0 | U11: 0 | V11: 0 | W11: 0 | X11: 0 | Y11: 0 | Z11: 0 | AA11: 0 | AB11: 0 | AC11: 0 | AD11: 0 | AE11: 0 | AF11: 0 | AG11: 0 | AH11: 0 | AI11: 0 | AJ11: 0 | AK11: 0 | AL11: 0 | AM11: 0 | AN11: 0 | AO11: 0 | AP11: 0 | AQ11: 0 | AR11: 1 | AS11: =SUM(J11:Q11) -> 2 | AT11: =SUM(R11:AR11) -> 3 | AU11: 画面美术场景；音乐音效配音；国产3A身份期待 | AV11: =IF(AT11>0,1,0) -> 1 | AW11: =IF(AT11=0,1,0) -> 0 | AX11: =IF(AT11>=8,1,0) -> 0 | AY11: 30.5 | AZ11: 正面 | BA11: P | BB11: 原文
A12: CN-P-011 | B12: 中文 | C12: 推荐 | D12: 8705 | E12: 422 | F12: 132.2 | G12: 2024-08-20 | H12: 黑猴出世耀寰球，雄姿飒爽震九州。 无畏妖魔横空舞，一棍破敌尽风流。 惩恶扬善翻天覆，千古传说又重修。 踏平坎坷成大道，白骨之后再西游。 庚子年七月初二，余与常入哔哩哔哩，顾举界面求之，只见热门榜首标题亦生亦熟：黑神话？悟空？实机演示？即入观之，既而疑、动、喜至怖之情盈盈于胸，终日不释，观毕，始知涕泗横流矣。 余自幼嗜游，经手之数，浩如烟海，或单机或网游，神游于西土人情，鏖战在异域殊方。然随游龄之长，吾常觉心中空矣。至此方醒——从未游玩我中华文化背景之大型单机哉！黑神话之壁画、经幢、佛像、猢狲、妖魔、古建、对白、山水、民乐……纵不念，身心之烙印安能去乎？ 余如久旱而逢甘霖，他乡而遇故知，官方演示，反复观之，更不解瘾，剧情设定之解析、天下洋人之嗟叹，及其二创观之不止。吾虽知其未售，如此吹捧，是不智也，然心之终信：名为悟空者，必不欲令人失望。 四年间，游戏科学者，踏实实更动态、勤恳恳制游戏。正是：拨开云雾见天日，守得云开见月明，掸落吾之隐忧。暇时，购本著补读之，复寻童时之忆——八六年《西游记》。临售，吾心之期愿不减，反而益大。是再款《大圣归来》，抑犹“国游之光”“乡中第一大学士”，今将共见之。 终末，以八六年西游记，列《大圣歌》词曰： 腾云驾雾 追风逐电 一个跟头 哈哈哈 十万八千 火眼金睛 铜头铁肩 威风凛凛 哈哈哈 大圣齐天 说什么 艰险磨难 怕什么 鬼怪神仙 掣开如意金箍棒 打它个地覆天也翻！ 掣开如意金箍棒 打它个地覆天 也翻！ 【好大圣，把毫毛拔了一把，嚼得粉碎，每一个和尚与他一截，都教他：“捻在无名指甲里，捻着拳头，只情走路。无人敢拿你便罢；若有人拿你，攒紧了拳头，叫一声‘齐天大圣’，我就来护你。”（摘于本著）】 以上皆为余心路之历程，待深度赏玩，复与诸君共赏~ ================================================================= 历经十日，九九归真，难满功成，有诗为证： 取经得正果，愿归花果山。 本事遭天忌，尽除还心安。 紧箍藏于首，不教人作乱。 身陨成六器，海枯石不烂。 天命得所聚，方能寻齐全。 贪欲焚不尽，黑风又烧山。 佛妖本同源，盗圣皆一念。 倒乱因和果，极乐非长远。 寻常最长久，此事古难全。 空负平天志，大力难抗天。 百战相惜别，折梅赠心猿。 六根齐聚终，残躯炼成丹。 二心化一意，齐天归真返。 走脱轮回路，还教闹翻天！ “哥哥们，饮了这杯，我们一起打上凌霄宝殿！” | I12: 黑猴出世耀寰球，雄姿飒爽震九州。 无畏妖魔横空舞，一棍破敌尽风流。 惩恶扬善翻天覆，千古传说又重修。 踏平坎坷成大道，白骨之后再西游。 庚子年七月初二，余与常入哔哩哔哩，顾举界面求之，只见热门榜首标题亦生亦熟：黑神话？悟空？实机演示？即入观之，既而疑、动、喜至怖之情盈盈于胸，终日不释，观毕，始知涕泗横流矣。 余自幼嗜游，经手之数，浩如烟海，或单机或网游，神游于西土人情，鏖战在异域殊方。然随游龄之长，吾常觉心中空矣。至此方醒——从未游玩我中华文化背景之大型单机哉！黑神话之壁画、经幢、佛像、猢狲、妖魔、古建、对白、山水、民乐……纵不念，身心之烙印安能去乎？ 余如久旱而逢甘霖，他乡而遇故知，官方演示，反复观之，更不解瘾，剧情设定之解析、天下洋人之嗟叹，及其二创观之不止。吾虽知其未售，如此吹捧，是不智也，然心之终信：名为悟空者，必不欲令人失望。 四年间，游戏科学者，踏实实更动态、勤恳恳制游戏。正是：拨开云雾见天日，守得云开见月明，掸落吾之隐忧。暇时，购本著补读之，复寻童时之忆——八六年《西游记》。临售，吾心之期愿不减，反而益大。是再款《大圣归来》，抑犹“国游之光”“乡中第一大学士”，今将共见之。 终末，以八六年西游记，列《大圣歌》词曰： 腾云驾雾 追风逐电 一个跟头 哈哈哈 十万八千 火眼金睛 铜头铁肩 威风凛凛 哈哈哈 大圣齐天 说什么 艰险磨难 怕什么 鬼怪神仙 掣开如意金箍棒 打它个地覆天也翻！ 掣开如意金箍棒 打它个地覆天 也翻！ 【好大圣，把毫毛拔了一把，嚼得粉碎，每一个和尚与他一截，都教他：“捻在无名指甲里，捻着拳头，只情走路。无人敢拿你便罢；若有人拿你，攒紧了拳头，叫一声‘齐天大圣’，我就来护你。”（摘于本著）】 以上皆为余心路之历程，待深度赏玩，复与诸君共赏~ ================================================================= 历经十日，九九归真，难满功成，有诗为证： 取经得正果，愿归花果山。 本事遭天忌，尽除还心安。 紧箍藏于首，不教人作乱。 身陨成六器，海枯石不烂。 天命得所聚，方能寻齐全。 贪欲焚不尽，黑风又烧山。 佛妖本同源，盗圣皆一念。 倒乱因和果，极乐非长远。 寻常最长久，此事古难全。 空负平天志，大力难抗天。 百战相惜别，折梅赠心猿。 六根齐聚终，残躯炼成丹。 二心化一意，齐天归真返。 走脱轮回路，还教闹翻天！ “哥哥们，饮了这杯，我们一起打上凌霄宝殿！” | J12: =IF(SUM(R12:T12)>0,1,0) -> 1 | K12: =IF(SUM(U12:Y12)>0,1,0) -> 1 | L12: =IF(SUM(Z12:AC12)>0,1,0) -> 0 | M12: =IF(SUM(AD12:AF12)>0,1,0) -> 0 | N12: =IF(SUM(AG12:AH12)>0,1,0) -> 1 | O12: =IF(SUM(AI12:AL12)>0,1,0) -> 1 | P12: =IF(SUM(AM12:AQ12)>0,1,0) -> 1 | Q12: =IF(AR12>0,1,0) -> 0 | R12: 1 | S12: 0 | T12: 0 | U12: 1 | V12: 0 | W12: 0 | X12: 0 | Y12: 0 | Z12: 0 | AA12: 0 | AB12: 0 | AC12: 0 | AD12: 0 | AE12: 0 | AF12: 0 | AG12: 0 | AH12: 1 | AI12: 1 | AJ12: 0 | AK12: 0 | AL12: 0 | AM12: 0 | AN12: 1 | AO12: 0 | AP12: 0 | AQ12: 0 | AR12: 0 | AS12: =SUM(J12:Q12) -> 5 | AT12: =SUM(R12:AR12) -> 5 | AU12: 画面美术场景；动作打击手感；推荐价值判断；西游悟空符号；原典知识人物关系专名 | AV12: =IF(AT12>0,1,0) -> 1 | AW12: =IF(AT12=0,1,0) -> 0 | AX12: =IF(AT12>=8,1,0) -> 0 | AY12: 7.5 | AZ12: 正面 | BA12: P | BB12: 原文
A13: CN-P-012 | B13: 中文 | C13: 推荐 | D13: 6708 | E13: 163 | F13: 70.5 | G13: 2024-08-20 | H13: 我有一个梦想，将来的某一天，大家都能玩到蕴含着中国上下五千年本土文化的优质游戏大作。我有一个梦想，有一天，西游记能出ACT，让老外去体会中国文化西游记中”斗战胜佛”的打击快感，那一定比西方的动作巅峰之作《战神》《鬼泣》更加深邃。我有一个梦想，有一天，上海滩能出沙盒游戏，而不是玩《GTA》感受美国梦，亦或是玩着《热血无赖》体验国外公司强行塞给我们的“中国文化”。我有一个梦想，有一天，不少3A大作不需要汉化，因为是我们自己的游戏，配音是中文，文化也是中国的。我有一个梦想，将来的某一天，国产游戏能像中国的其他产业一样，以一个领跑者的姿态，面对全世界，面对全宇宙，器宇轩昂，扬眉吐气。这会是由我们一起去完成的梦想。我等着我们的好消息。 ——毛星云 R.I.P我们好像快要做到了，但是很遗憾您看不到了。 | I13: 我有一个梦想，将来的某一天，大家都能玩到蕴含着中国上下五千年本土文化的优质游戏大作。我有一个梦想，有一天，西游记能出ACT，让老外去体会中国文化西游记中”斗战胜佛”的打击快感，那一定比西方的动作巅峰之作《战神》《鬼泣》更加深邃。我有一个梦想，有一天，上海滩能出沙盒游戏，而不是玩《GTA》感受美国梦，亦或是玩着《热血无赖》体验国外公司强行塞给我们的“中国文化”。我有一个梦想，有一天，不少3A大作不需要汉化，因为是我们自己的游戏，配音是中文，文化也是中国的。我有一个梦想，将来的某一天，国产游戏能像中国的其他产业一样，以一个领跑者的姿态，面对全世界，面对全宇宙，器宇轩昂，扬眉吐气。这会是由我们一起去完成的梦想。我等着我们的好消息。 ——毛星云 R.I.P我们好像快要做到了，但是很遗憾您看不到了。 | J13: =IF(SUM(R13:T13)>0,1,0) -> 1 | K13: =IF(SUM(U13:Y13)>0,1,0) -> 1 | L13: =IF(SUM(Z13:AC13)>0,1,0) -> 0 | M13: =IF(SUM(AD13:AF13)>0,1,0) -> 0 | N13: =IF(SUM(AG13:AH13)>0,1,0) -> 0 | O13: =IF(SUM(AI13:AL13)>0,1,0) -> 1 | P13: =IF(SUM(AM13:AQ13)>0,1,0) -> 0 | Q13: =IF(AR13>0,1,0) -> 1 | R13: 0 | S13: 1 | T13: 0 | U13: 1 | V13: 0 | W13: 0 | X13: 0 | Y13: 0 | Z13: 0 | AA13: 0 | AB13: 0 | AC13: 0 | AD13: 0 | AE13: 0 | AF13: 0 | AG13: 0 | AH13: 0 | AI13: 1 | AJ13: 0 | AK13: 0 | AL13: 1 | AM13: 0 | AN13: 0 | AO13: 0 | AP13: 0 | AQ13: 0 | AR13: 1 | AS13: =SUM(J13:Q13) -> 4 | AT13: =SUM(R13:AR13) -> 5 | AU13: 音乐音效配音；动作打击手感；西游悟空符号；中国文化宗教语言审美；国产3A身份期待 | AV13: =IF(AT13>0,1,0) -> 1 | AW13: =IF(AT13=0,1,0) -> 0 | AX13: =IF(AT13>=8,1,0) -> 0 | AY13: 15 | AZ13: 正面 | BA13: P | BB13: 原文
... A16: CN-P-015 | B16: 中文 | C16: 推荐 | D16: 812 | E16: 19 | F16: 18.6 | G16: 2024-08-20 | H16: 2024年8月20日，黑神话悟空发行，侄子想玩，但他当时已经高三开始上课了，约好了考上一本线，就送侄子豪华版。如果一切走在正轨上，侄子也许刚好高考完，黑神话刚好也打折，买豪华版我还能省点钱。但在参加高考前侄子因为意外离世了，甚至没能看见他展现自己苦读12年的努力，侄子也是一个普通的热爱着游戏的年轻人，你期待着热爱着的游戏，叔叔只能替你去见证了。 | I16: 2024年8月20日，黑神话悟空发行，侄子想玩，但他当时已经高三开始上课了，约好了考上一本线，就送侄子豪华版。如果一切走在正轨上，侄子也许刚好高考完，黑神话刚好也打折，买豪华版我还能省点钱。但在参加高考前侄子因为意外离世了，甚至没能看见他展现自己苦读12年的努力，侄子也是一个普通的热爱着游戏的年轻人，你期待着热爱着的游戏，叔叔只能替你去见证了。 | J16: =IF(SUM(R16:T16)>0,1,0) -> 0 | K16: =IF(SUM(U16:Y16)>0,1,0) -> 0 | L16: =IF(SUM(Z16:AC16)>0,1,0) -> 0 | M16: =IF(SUM(AD16:AF16)>0,1,0) -> 0 | N16: =IF(SUM(AG16:AH16)>0,1,0) -> 1 | O16: =IF(SUM(AI16:AL16)>0,1,0) -> 1 | P16: =IF(SUM(AM16:AQ16)>0,1,0) -> 0 | Q16: =IF(AR16>0,1,0) -> 0 | R16: 0 | S16: 0 | T16: 0 | U16: 0 | V16: 0 | W16: 0 | X16: 0 | Y16: 0 | Z16: 0 | AA16: 0 | AB16: 0 | AC16: 0 | AD16: 0 | AE16: 0 | AF16: 0 | AG16: 0 | AH16: 1 | AI16: 1 | AJ16: 0 | AK16: 0 | AL16: 0 | AM16: 0 | AN16: 0 | AO16: 0 | AP16: 0 | AQ16: 0 | AR16: 0 | AS16: =SUM(J16:Q16) -> 2 | AT16: =SUM(R16:AR16) -> 2 | AU16: 推荐价值判断；西游悟空符号 | AV16: =IF(AT16>0,1,0) -> 1 | AW16: =IF(AT16=0,1,0) -> 0 | AX16: =IF(AT16>=8,1,0) -> 0 | AY16: 8.5 | AZ16: 正面 | BA16: P | BB16: 原文
A17: CN-P-016 | B17: 中文 | C17: 推荐 | D17: 0 | E17: 0 | F17: 23.9 小时 | G17: 2024-08-21 | H17: 除了画质其他的部分一言难尽，第二章的和第三章的地图设计简直就是重量级，怪物设计前面的感觉都挺不错的，从黄风开始就初现端倪。黄风也是重量级，已经看到有不少人骂了，作为关底boss待遇和普通怪一样，路过还以为是要顺手打的精英怪，定风丹一点引导都没有，但凡你在我似了几次后蹦出来一个npc让我去拿个丹，或者哪怕只是一个转场动画的tips告诉我还有这玩意我都能说你有引导，一点引导都没有真的是逆天了，别跟我提原著或者上网查，提原著的简直就是好笑，自己游戏一点引导没有指望玩家做攻略全都自己搞定？你游戏又没地图又没明确的引导，地图又做的逆天，群里迷路的一大堆，你跟我说是自己问题？还是说你要给我扯什么游戏的意义了？我欣赏不来这种艺术，哥们就想把boss都打了。地图方面真的无力吐槽，要来批判我自己不认真玩游戏的建议去看看各大主播的迷路率，第二章的地图标识物太少，没有路牌也没有什么记忆点，第三章无力吐槽，只能说玩了的懂得都懂。战斗设计上仁者见仁智者见智，有夸的有骂的，我感觉比较一般，无功无过。但boss设计真的是重量级，前面一二章的boss打的都挺爽的，但从第三章开始设计质量就是断崖式的下滑，难度不高但恶心程度极其逆天，喜欢我刮了10分钟被削了血量上限后被一招反杀吗，菜就多练？玩不过就别玩？不是打不打得过的问题，打亢金龙我也是两遍过，但战斗体验可以说差到了极致，然后跑图真实模拟坐大牢后遇到一个活全家的必打boss，前三章最粪boss没人有意见吧？视角乱的好像头被拧断了一样，血量上限减半就算了，这个战斗过程中各种无伤害强制打断动作。我就不明白了，虎先锋卡住了很多新手玩家但我寻思也没人在设计上骂他，让玩家战斗爽有那么难吗？各种小boss没有引导，明明看着有路却有空气墙，看着一眼空气墙的地方又可以走了。哥们没那么有钱，268对我来说不少了，哥们花这么多买了个游戏这么明显的缺点这么多，美术音乐确实是顶级，剧情我没看完不做评价。我说的很清楚了，游戏性上体验相当差，但除此之外的地方都很好，作为国产第一款3a我可以理解，但不好就是不好。给一些修改意见：1.修改索敌大体积怪物时的视角问题。2.增加地图引导，可以添加小地图道具，哪怕只是在背包中才能看也行。3.为地图增加有记忆点的地标，有效防止各种迷路。在tips中或者npc对话中添加关卡引导，把关底boss和一般boss做更加明显的区分。4.独木桥弓箭手活全家。5.建议第三章整体重做，我白天坐牢已经坐够了晚上真不想回家还沉浸式坐牢。 | I17: 除了画质其他的部分一言难尽，第二章的和第三章的地图设计简直就是重量级，怪物设计前面的感觉都挺不错的，从黄风开始就初现端倪。黄风也是重量级，已经看到有不少人骂了，作为关底boss待遇和普通怪一样，路过还以为是要顺手打的精英怪，定风丹一点引导都没有，但凡你在我似了几次后蹦出来一个npc让我去拿个丹，或者哪怕只是一个转场动画的tips告诉我还有这玩意我都能说你有引导，一点引导都没有真的是逆天了，别跟我提原著或者上网查，提原著的简直就是好笑，自己游戏一点引导没有指望玩家做攻略全都自己搞定？你游戏又没地图又没明确的引导，地图又做的逆天，群里迷路的一大堆，你跟我说是自己问题？还是说你要给我扯什么游戏的意义了？我欣赏不来这种艺术，哥们就想把boss都打了。地图方面真的无力吐槽，要来批判我自己不认真玩游戏的建议去看看各大主播的迷路率，第二章的地图标识物太少，没有路牌也没有什么记忆点，第三章无力吐槽，只能说玩了的懂得都懂。战斗设计上仁者见仁智者见智，有夸的有骂的，我感觉比较一般，无功无过。但boss设计真的是重量级，前面一二章的boss打的都挺爽的，但从第三章开始设计质量就是断崖式的下滑，难度不高但恶心程度极其逆天，喜欢我刮了10分钟被削了血量上限后被一招反杀吗，菜就多练？玩不过就别玩？不是打不打得过的问题，打亢金龙我也是两遍过，但战斗体验可以说差到了极致，然后跑图真实模拟坐大牢后遇到一个活全家的必打boss，前三章最粪boss没人有意见吧？视角乱的好像头被拧断了一样，血量上限减半就算了，这个战斗过程中各种无伤害强制打断动作。我就不明白了，虎先锋卡住了很多新手玩家但我寻思也没人在设计上骂他，让玩家战斗爽有那么难吗？各种小boss没有引导，明明看着有路却有空气墙，看着一眼空气墙的地方又可以走了。哥们没那么有钱，268对我来说不少了，哥们花这么多买了个游戏这么明显的缺点这么多，美术音乐确实是顶级，剧情我没看完不做评价。我说的很清楚了，游戏性上体验相当差，但除此之外的地方都很好，作为国产第一款3a我可以理解，但不好就是不好。给一些修改意见：1.修改索敌大体积怪物时的视角问题。2.增加地图引导，可以添加小地图道具，哪怕只是在背包中才能看也行。3.为地图增加有记忆点的地标，有效防止各种迷路。在tips中或者npc对话中添加关卡引导，把关底boss和一般boss做更加明显的区分。4.独木桥弓箭手活全家。5.建议第三章整体重做，我白天坐牢已经坐够了晚上真不想回家还沉浸式坐牢。 | J17: =IF(SUM(R17:T17)>0,1,0) -> 1 | K17: =IF(SUM(U17:Y17)>0,1,0) -> 1 | L17: =IF(SUM(Z17:AC17)>0,1,0) -> 1 | M17: =IF(SUM(AD17:AF17)>0,1,0) -> 0 | N17: =IF(SUM(AG17:AH17)>0,1,0) -> 1 | O17: =IF(SUM(AI17:AL17)>0,1,0) -> 1 | P17: =IF(SUM(AM17:AQ17)>0,1,0) -> 1 | Q17: =IF(AR17>0,1,0) -> 1 | R17: 1 | S17: 1 | T17: 1 | U17: 1 | V17: 1 | W17: 1 | X17: 1 | Y17: 0 | Z17: 1 | AA17: 1 | AB17: 1 | AC17: 1 | AD17: 0 | AE17: 0 | AF17: 0 | AG17: 1 | AH17: 1 | AI17: 0 | AJ17: 0 | AK17: 1 | AL17: 1 | AM17: 0 | AN17: 0 | AO17: 0 | AP17: 1 | AQ17: 0 | AR17: 1 | AS17: =SUM(J17:Q17) -> 7 | AT17: =SUM(R17:AR17) -> 17 | AU17: 画面美术场景；音乐音效配音；演出角色怪物设计；动作打击手感；Boss战斗节奏；难度挑战；锁定视角；地图路线；空气墙可达性；探索隐藏支线；引导迷路单线；整体完成度；推荐价值判断；本国媒介路径；中国文化宗教语言审美；外部资料依赖；国产3A身份期待 | AV17: =IF(AT17>0,1,0) -> 1 | AW17: =IF(AT17=0,1,0) -> 0 | AX17: =IF(AT17>=8,1,0) -> 1 | AY17: 4.5 | AZ17: 正面 | BA17: P | BB17: 原文
A18: CN-P-017 | B18: 中文 | C18: 推荐 | D18: 303 | E18: 6 | F18: 36.3 | G18: 2024-08-20 | H18: 黑神话作为3A游戏是不完美的，甚至是不太成熟的，但是对于中国玩家他是目前最好的3A游戏 对国内玩家而言，今天是一个值得铭记的一天。但是我不想谈情怀，而是理性看待游戏。抛开立场，冷静分析后，我相信各位游戏爱好者在体验了许多成熟的3A作品后，会发现《黑神话》确实存在不少不足之处。就像A9评测说的那样：”它不需要被包容，也不需要被捧上神坛“ 指出这些不足，才能推动国内游戏的发展更快更好！《黑神话》的美术水平无疑达到了全球顶尖，但是我建议游科开除关卡策划（我感觉大概率是因为美术主导才导致的）。 其实我的个人期望最开始就没有拉到很高，希望能和《仁王》一个水平即可。随着发售日期的临近，官方尚未发布玩家试玩Demo，我开始感到一些不安。最终体验下来，整体可玩性确实不及《仁王》。更严苛地评价的话，我感觉它更像是2024年的《教团1886》的升级版，美术水平和设计能力严重不匹配。比如，大家以及评测媒体都提到的“地图迷路”问题 小地图可以解决部分问题，但是会可能影响沉浸感 。虽然有人认为“迷路”只是一个小瑕疵，但是在重复十几次之后一定会产生强烈的负面情绪。因为这本身就是关卡设计中的一大忌讳。《黑神话》在关卡设计上不应与魂类游戏相比，因为魂类游戏注重小型箱庭地图的通路设计，包括捷径、隐藏奖励、稀有敌人等一整套系统，能够有效地使玩家的情绪产生反馈。如果拿传统线性游戏做参考，则可以通过场景中的材质变化提示、可交互或可破坏物的引导等方式，减少迷路的可能性，虽然这些可能会影响场景的氛围，但它们确实能粗暴地解决一些问题。这让我不禁想起顽皮狗的关卡设计，其巧妙的指引方式，包括环境解谜、狭窄通路设计和角色互动等，充分展示了优秀的关卡设计理念。 感兴趣可以看看这个，顽皮狗关卡设计师的分享 [www.bilibili.com]这些问题充分说明，《黑神话》在设计层面仍显得不够成熟，无法和美术能力做匹配，给我的感觉更像是由美术主导完成的关卡设计。黑神话可能拿不到今年的Glory，但是它绝对是中国游戏的Glory。 即便它撼动不了资本的地位，若能让国家政策开始倾斜的话，结果会更好！隔壁韩国游戏行业能发展壮大起来，我们一定也没问题的！ | I18: 黑神话作为3A游戏是不完美的，甚至是不太成熟的，但是对于中国玩家他是目前最好的3A游戏 对国内玩家而言，今天是一个值得铭记的一天。但是我不想谈情怀，而是理性看待游戏。抛开立场，冷静分析后，我相信各位游戏爱好者在体验了许多成熟的3A作品后，会发现《黑神话》确实存在不少不足之处。就像A9评测说的那样：”它不需要被包容，也不需要被捧上神坛“ 指出这些不足，才能推动国内游戏的发展更快更好！《黑神话》的美术水平无疑达到了全球顶尖，但是我建议游科开除关卡策划（我感觉大概率是因为美术主导才导致的）。 其实我的个人期望最开始就没有拉到很高，希望能和《仁王》一个水平即可。随着发售日期的临近，官方尚未发布玩家试玩Demo，我开始感到一些不安。最终体验下来，整体可玩性确实不及《仁王》。更严苛地评价的话，我感觉它更像是2024年的《教团1886》的升级版，美术水平和设计能力严重不匹配。比如，大家以及评测媒体都提到的“地图迷路”问题 小地图可以解决部分问题，但是会可能影响沉浸感 。虽然有人认为“迷路”只是一个小瑕疵，但是在重复十几次之后一定会产生强烈的负面情绪。因为这本身就是关卡设计中的一大忌讳。《黑神话》在关卡设计上不应与魂类游戏相比，因为魂类游戏注重小型箱庭地图的通路设计，包括捷径、隐藏奖励、稀有敌人等一整套系统，能够有效地使玩家的情绪产生反馈。如果拿传统线性游戏做参考，则可以通过场景中的材质变化提示、可交互或可破坏物的引导等方式，减少迷路的可能性，虽然这些可能会影响场景的氛围，但它们确实能粗暴地解决一些问题。这让我不禁想起顽皮狗的关卡设计，其巧妙的指引方式，包括环境解谜、狭窄通路设计和角色互动等，充分展示了优秀的关卡设计理念。 感兴趣可以看看这个，顽皮狗关卡设计师的分享 [www.bilibili.com]这些问题充分说明，《黑神话》在设计层面仍显得不够成熟，无法和美术能力做匹配，给我的感觉更像是由美术主导完成的关卡设计。黑神话可能拿不到今年的Glory，但是它绝对是中国游戏的Glory。 即便它撼动不了资本的地位，若能让国家政策开始倾斜的话，结果会更好！隔壁韩国游戏行业能发展壮大起来，我们一定也没问题的！ | J18: =IF(SUM(R18:T18)>0,1,0) -> 1 | K18: =IF(SUM(U18:Y18)>0,1,0) -> 1 | L18: =IF(SUM(Z18:AC18)>0,1,0) -> 1 | M18: =IF(SUM(AD18:AF18)>0,1,0) -> 0 | N18: =IF(SUM(AG18:AH18)>0,1,0) -> 1 | O18: =IF(SUM(AI18:AL18)>0,1,0) -> 1 | P18: =IF(SUM(AM18:AQ18)>0,1,0) -> 0 | Q18: =IF(AR18>0,1,0) -> 1 | R18: 1 | S18: 0 | T18: 1 | U18: 0 | V18: 0 | W18: 0 | X18: 0 | Y18: 1 | Z18: 1 | AA18: 0 | AB18: 1 | AC18: 1 | AD18: 0 | AE18: 0 | AF18: 0 | AG18: 1 | AH18: 1 | AI18: 0 | AJ18: 1 | AK18: 0 | AL18: 0 | AM18: 0 | AN18: 0 | AO18: 0 | AP18: 0 | AQ18: 0 | AR18: 1 | AS18: =SUM(J18:Q18) -> 6 | AT18: =SUM(R18:AR18) -> 10 | AU18: 画面美术场景；演出角色怪物设计；判定反馈；地图路线；探索隐藏支线；引导迷路单线；整体完成度；推荐价值判断；童年记忆情怀；国产3A身份期待 | AV18: =IF(AT18>0,1,0) -> 1 | AW18: =IF(AT18=0,1,0) -> 0 | AX18: =IF(AT18>=8,1,0) -> 1 | AY18: 15.5 | AZ18: 正面 | BA18: P | BB18: 原文
A19: CN-P-018 | B19: 中文 | C19: 推荐 | D19: 286 | E19: 2 | F19: 17.4 | G19: 2024-08-20 | H19: 作为国产第一款3a游戏我认为这个表现相当可以了，这是我玩了三个小时的真心感受。我看大家都在夸我就说几个我在意的地方供大伙以及游科参考。第一点，在打灵虚子的时候他在我身边跑动，出现了丢失视野的情况。就是锁定还在但是屏幕里没有BOSS，我认为是BOSS跑得太快以及镜头运转太慢导致的。等BOSS停下来了之后镜头又正常了。不过不是什么大问题，BOSS这个时候不会偷袭，况且灵虚子是前面最菜的一个BOSS第二点，游戏里面场景做的太好了，有些不能走的地方经常会让我撞得满头包，还有有的地方可以跳过去有的类似的地形就不可以，但地图是真大啊。第三点，我认为可以出一个保存加点的机制。没有死亡惩罚以及有偿洗点对我来讲已经非常非常棒了，但这个加点如果能作为一个范式保留的话就更好了总而言之，这款游戏没有辜负大伙四年的等待，纵使有一些瑕疵但是瑕不掩瑜，在做的好的地方已经足够好了，我会继续玩下去，后面会继续更新 | I19: 作为国产第一款3a游戏我认为这个表现相当可以了，这是我玩了三个小时的真心感受。我看大家都在夸我就说几个我在意的地方供大伙以及游科参考。第一点，在打灵虚子的时候他在我身边跑动，出现了丢失视野的情况。就是锁定还在但是屏幕里没有BOSS，我认为是BOSS跑得太快以及镜头运转太慢导致的。等BOSS停下来了之后镜头又正常了。不过不是什么大问题，BOSS这个时候不会偷袭，况且灵虚子是前面最菜的一个BOSS第二点，游戏里面场景做的太好了，有些不能走的地方经常会让我撞得满头包，还有有的地方可以跳过去有的类似的地形就不可以，但地图是真大啊。第三点，我认为可以出一个保存加点的机制。没有死亡惩罚以及有偿洗点对我来讲已经非常非常棒了，但这个加点如果能作为一个范式保留的话就更好了总而言之，这款游戏没有辜负大伙四年的等待，纵使有一些瑕疵但是瑕不掩瑜，在做的好的地方已经足够好了，我会继续玩下去，后面会继续更新 | J19: =IF(SUM(R19:T19)>0,1,0) -> 1 | K19: =IF(SUM(U19:Y19)>0,1,0) -> 1 | L19: =IF(SUM(Z19:AC19)>0,1,0) -> 1 | M19: =IF(SUM(AD19:AF19)>0,1,0) -> 0 | N19: =IF(SUM(AG19:AH19)>0,1,0) -> 0 | O19: =IF(SUM(AI19:AL19)>0,1,0) -> 0 | P19: =IF(SUM(AM19:AQ19)>0,1,0) -> 0 | Q19: =IF(AR19>0,1,0) -> 1 | R19: 1 | S19: 0 | T19: 0 | U19: 0 | V19: 1 | W19: 1 | X19: 1 | Y19: 0 | Z19: 1 | AA19: 1 | AB19: 0 | AC19: 0 | AD19: 0 | AE19: 0 | AF19: 0 | AG19: 0 | AH19: 0 | AI19: 0 | AJ19: 0 | AK19: 0 | AL19: 0 | AM19: 0 | AN19: 0 | AO19: 0 | AP19: 0 | AQ19: 0 | AR19: 1 | AS19: =SUM(J19:Q19) -> 4 | AT19: =SUM(R19:AR19) -> 7 | AU19: 画面美术场景；Boss战斗节奏；难度挑战；锁定视角；地图路线；空气墙可达性；国产3A身份期待 | AV19: =IF(AT19>0,1,0) -> 1 | AW19: =IF(AT19=0,1,0) -> 0 | AX19: =IF(AT19>=8,1,0) -> 0 | AY19: 14 | AZ19: 正面 | BA19: P | BB19: 原文
A20: CN-P-019 | B20: 中文 | C20: 不推荐 | D20: 259 | E20: 19 | F20: 46.7 | G20: 2024-08-20 | H20: 好评没两个说游戏怎么样的，就是无脑好评，饭圈滚出steam | I20: 好评没两个说游戏怎么样的，就是无脑好评，饭圈滚出steam | J20: =IF(SUM(R20:T20)>0,1,0) -> 0 | K20: =IF(SUM(U20:Y20)>0,1,0) -> 0 | L20: =IF(SUM(Z20:AC20)>0,1,0) -> 0 | M20: =IF(SUM(AD20:AF20)>0,1,0) -> 0 | N20: =IF(SUM(AG20:AH20)>0,1,0) -> 0 | O20: =IF(SUM(AI20:AL20)>0,1,0) -> 0 | P20: =IF(SUM(AM20:AQ20)>0,1,0) -> 0 | Q20: =IF(AR20>0,1,0) -> 0 | R20: 0 | S20: 0 | T20: 0 | U20: 0 | V20: 0 | W20: 0 | X20: 0 | Y20: 0 | Z20: 0 | AA20: 0 | AB20: 0 | AC20: 0 | AD20: 0 | AE20: 0 | AF20: 0 | AG20: 0 | AH20: 0 | AI20: 0 | AJ20: 0 | AK20: 0 | AL20: 0 | AM20: 0 | AN20: 0 | AO20: 0 | AP20: 0 | AQ20: 0 | AR20: 0 | AS20: =SUM(J20:Q20) -> 0 | AT20: =SUM(R20:AR20) -> 0 | AV20: =IF(AT20>0,1,0) -> 0 | AW20: =IF(AT20=0,1,0) -> 1 | AX20: =IF(AT20>=8,1,0) -> 0 | AY20: 3 | AZ20: 正面 | BA20: P | BB20: 原文
A21: CN-P-020 | B21: 中文 | C21: 不推荐 | D21: 245 | E21: 70 | F21: 3.3 | G21: 2024-08-20 | H21: 一坨不好惹的屎可以完美的概括这款游戏 | I21: 一坨不好惹的屎可以完美的概括这款游戏 | J21: =IF(SUM(R21:T21)>0,1,0) -> 0 | K21: =IF(SUM(U21:Y21)>0,1,0) -> 0 | L21: =IF(SUM(Z21:AC21)>0,1,0) -> 0 | M21: =IF(SUM(AD21:AF21)>0,1,0) -> 0 | N21: =IF(SUM(AG21:AH21)>0,1,0) -> 0 | O21: =IF(SUM(AI21:AL21)>0,1,0) -> 0 | P21: =IF(SUM(AM21:AQ21)>0,1,0) -> 0 | Q21: =IF(AR21>0,1,0) -> 0 | R21: 0 | S21: 0 | T21: 0 | U21: 0 | V21: 0 | W21: 0 | X21: 0 | Y21: 0 | Z21: 0 | AA21: 0 | AB21: 0 | AC21: 0 | AD21: 0 | AE21: 0 | AF21: 0 | AG21: 0 | AH21: 0 | AI21: 0 | AJ21: 0 | AK21: 0 | AL21: 0 | AM21: 0 | AN21: 0 | AO21: 0 | AP21: 0 | AQ21: 0 | AR21: 0 | AS21: =SUM(J21:Q21) -> 0 | AT21: =SUM(R21:AR21) -> 0 | AV21: =IF(AT21>0,1,0) -> 0 | AW21: =IF(AT21=0,1,0) -> 1 | AX21: =IF(AT21>=8,1,0) -> 0 | AY21: 1 | AZ21: 正面 | BA21: P | BB21: 原文
A22: CN-P-021 | B22: 中文 | C22: 推荐 | D22: 227 | E22: 4 | F22: 45.9 | G22: 2024-08-20 | H22: 豪玩但是！我需要：1：手柄自定义键位！！！！！！2：短按闪避长按奔跑3：奔跑跳跃后保持奔跑状态 | I22: 豪玩但是！我需要：1：手柄自定义键位！！！！！！2：短按闪避长按奔跑3：奔跑跳跃后保持奔跑状态 | J22: =IF(SUM(R22:T22)>0,1,0) -> 0 | K22: =IF(SUM(U22:Y22)>0,1,0) -> 1 | L22: =IF(SUM(Z22:AC22)>0,1,0) -> 0 | M22: =IF(SUM(AD22:AF22)>0,1,0) -> 0 | N22: =IF(SUM(AG22:AH22)>0,1,0) -> 0 | O22: =IF(SUM(AI22:AL22)>0,1,0) -> 0 | P22: =IF(SUM(AM22:AQ22)>0,1,0) -> 0 | Q22: =IF(AR22>0,1,0) -> 0 | R22: 0 | S22: 0 | T22: 0 | U22: 1 | V22: 0 | W22: 0 | X22: 0 | Y22: 0 | Z22: 0 | AA22: 0 | AB22: 0 | AC22: 0 | AD22: 0 | AE22: 0 | AF22: 0 | AG22: 0 | AH22: 0 | AI22: 0 | AJ22: 0 | AK22: 0 | AL22: 0 | AM22: 0 | AN22: 0 | AO22: 0 | AP22: 0 | AQ22: 0 | AR22: 0 | AS22: =SUM(J22:Q22) -> 1 | AT22: =SUM(R22:AR22) -> 1 | AU22: 动作打击手感 | AV22: =IF(AT22>0,1,0) -> 1 | AW22: =IF(AT22=0,1,0) -> 0 | AX22: =IF(AT22>=8,1,0) -> 0 | AY22: 2 | AZ22: 正面 | BA22: P | BB22: 原文
A23: CN-P-022 | B23: 中文 | C23: 不推荐 | D23: 212 | E23: 15 | F23: 67.3 | G23: 2024-08-20 | H23: 请问第三章真的是人设计的吗？？是脑子有什么病吗？很好玩吗？很有趣吗？你们玩过吗？你们很喜欢吗？？我不理解。全成就了，现在感觉能正常且系统性的来评价这款游戏了。对于我来说，一周目的第一章的体验是极其美好的，不算复杂的地图设计就没有地图与指引全收集也不是难事，但是在第二章的大规模地图的设计下就开始变味儿。因为没有地图与指引，人物就像乱转的苍蝇，再加上游科也确确实实喜欢在地图里藏物品和任务，导致玩家只能把看到的位置都探索一遍，然后产生了一种灾难性的体验，就是探索空气墙，这一点在第三章尤为体现。随后而来的第四章的地图设计我反而更能接受，个人认为第四章地图的辨识度比第三章高很多，且比起大平面的地图个人也更喜欢纵向的地图设计。能感觉到游科在制作游戏的时候想给玩家呈现不同的地图设计但是我并不认为不给玩家地图功能是一个能忽略的缺点。说回让我破防的第三章的浮屠牢，我深深地感到来自于制作人的恶意，确确实实是真实的坐牢体验。在人物没有靠谱的远程手段且前期法力并不可再生只能去土地庙才能回复的条件下，给我的游戏体验是极其糟糕的，经典的斜坡或者独木桥旁放远程和让你坠机飞天小怪，再搭配上每隔几分钟人物血量减半的debuff，堪称折磨。就算经历万险，爬出牢笼，别忘了头上可有个还能给你带来糟糕体验的boss。说句实话，黑神话给我与boss的战斗体验也是扣分的，基本上每个boss都会有一到两个招数他会飞到空中而你只能在地面一边疯狂逃窜一边干瞪眼。boss会一边在空中跳舞一边免疫你引以为豪的定身术。我能理解游科的部分想法，那就是法宝克制，比如说收集到第二章的隐藏法宝，确确实实就能跳过boss的跳舞阶段，这设计思路我觉得很棒，很喜欢，但是其他的boss呢，一周目能像这样跳过阶段的boss又有几个呢？除了强制对舞pk以外，再就是快慢刀了，这点在二郎神身上算是体现到了极致。一道金光二郎显圣真君瞬移到你头上举起自己的开山斧，而你选择铜墙铁壁硬挡这一斧，但很遗憾直到你的铜墙铁壁结束，二郎神的斧才会劈下来。我本来期望会有酣畅淋漓，大开大合的一场战斗，可打着打着，只能一边嘴巴上爆着粗口一边祭出卑鄙的芭蕉扇。等打完也不会是与强敌对战后的意犹未竟而是感觉出了一口恶气。其实战斗方面还有很多可以聊的，糟糕的锁定，我打巨人的脚，锁左脚往裆下打，锁右脚还是往裆下打。部分敌人的韧性极高，而我们主角被一把小刀划到可能就会被打断，更别提我主玩的劈棍好不容易攒好豆被打断伴随始终。不过劈棍更大问题还是距离太短太容易空，被体型大一点的模型碰撞一下就会登龙失败，其他的流派做得到吗？还有预输入，个人还是更倾向于有预输入的战斗体验。对我来说，黑神话悟空是一款优点缺点都极其明显的游戏，他有着让人着迷的美术音乐设计和头目演出，对于出现过的神人妖都会有专门的游记进行记载，既丰富了世界观也满足了玩家对于剧情探索的需求，更别提是基于国人耳熟能详的西游记的再创作。但同时他又有着略偏同质化的战斗及部分糟糕的boss战体验，个别章节的地图设计恶意满满，还有绝对应该有却没有的地图功能以及指引。这种优缺点明显的游戏让我觉得在互联网上夸的骂的，都很正常。但是只让人骂见不得夸的，或者只让人夸见不得骂的，除了云玩家、串子再就是一些我不太好说的饭圈团体了。不过看了看大家给我的留言，互联网上的大家绝大部分还是很温和的正常人。最后就是，我也是第一次写这种长评测，当时破防也是确确实实被游戏设计震惊且觉得恶心，现在刚刚白金也是感概万千，真实的取经体验，苦甜参半，个中滋味也确实令人回味。脑子乱糟糟也写得也是乱糟糟但这也算是我黑神话之旅最真实的感受了。也希望游科能够重视这次黑神话的部分糟糕体验，在后续dlc及作品里做出改善。另外二周目是真的爽，如果一周目让你玩的不开心这不是你心中的大圣，二周目绝对会满足你对大圣的幻想。 | I23: 请问第三章真的是人设计的吗？？是脑子有什么病吗？很好玩吗？很有趣吗？你们玩过吗？你们很喜欢吗？？我不理解。全成就了，现在感觉能正常且系统性的来评价这款游戏了。对于我来说，一周目的第一章的体验是极其美好的，不算复杂的地图设计就没有地图与指引全收集也不是难事，但是在第二章的大规模地图的设计下就开始变味儿。因为没有地图与指引，人物就像乱转的苍蝇，再加上游科也确确实实喜欢在地图里藏物品和任务，导致玩家只能把看到的位置都探索一遍，然后产生了一种灾难性的体验，就是探索空气墙，这一点在第三章尤为体现。随后而来的第四章的地图设计我反而更能接受，个人认为第四章地图的辨识度比第三章高很多，且比起大平面的地图个人也更喜欢纵向的地图设计。能感觉到游科在制作游戏的时候想给玩家呈现不同的地图设计但是我并不认为不给玩家地图功能是一个能忽略的缺点。说回让我破防的第三章的浮屠牢，我深深地感到来自于制作人的恶意，确确实实是真实的坐牢体验。在人物没有靠谱的远程手段且前期法力并不可再生只能去土地庙才能回复的条件下，给我的游戏体验是极其糟糕的，经典的斜坡或者独木桥旁放远程和让你坠机飞天小怪，再搭配上每隔几分钟人物血量减半的debuff，堪称折磨。就算经历万险，爬出牢笼，别忘了头上可有个还能给你带来糟糕体验的boss。说句实话，黑神话给我与boss的战斗体验也是扣分的，基本上每个boss都会有一到两个招数他会飞到空中而你只能在地面一边疯狂逃窜一边干瞪眼。boss会一边在空中跳舞一边免疫你引以为豪的定身术。我能理解游科的部分想法，那就是法宝克制，比如说收集到第二章的隐藏法宝，确确实实就能跳过boss的跳舞阶段，这设计思路我觉得很棒，很喜欢，但是其他的boss呢，一周目能像这样跳过阶段的boss又有几个呢？除了强制对舞pk以外，再就是快慢刀了，这点在二郎神身上算是体现到了极致。一道金光二郎显圣真君瞬移到你头上举起自己的开山斧，而你选择铜墙铁壁硬挡这一斧，但很遗憾直到你的铜墙铁壁结束，二郎神的斧才会劈下来。我本来期望会有酣畅淋漓，大开大合的一场战斗，可打着打着，只能一边嘴巴上爆着粗口一边祭出卑鄙的芭蕉扇。等打完也不会是与强敌对战后的意犹未竟而是感觉出了一口恶气。其实战斗方面还有很多可以聊的，糟糕的锁定，我打巨人的脚，锁左脚往裆下打，锁右脚还是往裆下打。部分敌人的韧性极高，而我们主角被一把小刀划到可能就会被打断，更别提我主玩的劈棍好不容易攒好豆被打断伴随始终。不过劈棍更大问题还是距离太短太容易空，被体型大一点的模型碰撞一下就会登龙失败，其他的流派做得到吗？还有预输入，个人还是更倾向于有预输入的战斗体验。对我来说，黑神话悟空是一款优点缺点都极其明显的游戏，他有着让人着迷的美术音乐设计和头目演出，对于出现过的神人妖都会有专门的游记进行记载，既丰富了世界观也满足了玩家对于剧情探索的需求，更别提是基于国人耳熟能详的西游记的再创作。但同时他又有着略偏同质化的战斗及部分糟糕的boss战体验，个别章节的地图设计恶意满满，还有绝对应该有却没有的地图功能以及指引。这种优缺点明显的游戏让我觉得在互联网上夸的骂的，都很正常。但是只让人骂见不得夸的，或者只让人夸见不得骂的，除了云玩家、串子再就是一些我不太好说的饭圈团体了。不过看了看大家给我的留言，互联网上的大家绝大部分还是很温和的正常人。最后就是，我也是第一次写这种长评测，当时破防也是确确实实被游戏设计震惊且觉得恶心，现在刚刚白金也是感概万千，真实的取经体验，苦甜参半，个中滋味也确实令人回味。脑子乱糟糟也写得也是乱糟糟但这也算是我黑神话之旅最真实的感受了。也希望游科能够重视这次黑神话的部分糟糕体验，在后续dlc及作品里做出改善。另外二周目是真的爽，如果一周目让你玩的不开心这不是你心中的大圣，二周目绝对会满足你对大圣的幻想。 | J23: =IF(SUM(R23:T23)>0,1,0) -> 1 | K23: =IF(SUM(U23:Y23)>0,1,0) -> 1 | L23: =IF(SUM(Z23:AC23)>0,1,0) -> 1 | M23: =IF(SUM(AD23:AF23)>0,1,0) -> 0 | N23: =IF(SUM(AG23:AH23)>0,1,0) -> 1 | O23: =IF(SUM(AI23:AL23)>0,1,0) -> 1 | P23: =IF(SUM(AM23:AQ23)>0,1,0) -> 1 | Q23: =IF(AR23>0,1,0) -> 0 | R23: 1 | S23: 1 | T23: 1 | U23: 1 | V23: 1 | W23: 1 | X23: 1 | Y23: 1 | Z23: 1 | AA23: 1 | AB23: 1 | AC23: 1 | AD23: 0 | AE23: 0 | AF23: 0 | AG23: 0 | AH23: 1 | AI23: 1 | AJ23: 0 | AK23: 0 | AL23: 0 | AM23: 0 | AN23: 0 | AO23: 0 | AP23: 0 | AQ23: 1 | AR23: 0 | AS23: =SUM(J23:Q23) -> 6 | AT23: =SUM(R23:AR23) -> 15 | AU23: 画面美术场景；音乐音效配音；演出角色怪物设计；动作打击手感；Boss战斗节奏；难度挑战；锁定视角；判定反馈；地图路线；空气墙可达性；探索隐藏支线；引导迷路单线；推荐价值判断；西游悟空符号；角色期待意义偏移 | AV23: =IF(AT23>0,1,0) -> 1 | AW23: =IF(AT23=0,1,0) -> 0 | AX23: =IF(AT23>=8,1,0) -> 1 | AY23: 65.5 | AZ23: 正面 | BA23: P | BB23: 原文
A24: CN-P-023 | B24: 中文 | C24: 推荐 | D24: 188 | E24: 228 | F24: 41.2 | G24: 2024-08-20 | H24: 免费获取的产品 给兄弟口了一整天才给买的，好玩 | I24: 免费获取的产品 给兄弟口了一整天才给买的，好玩 | J24: =IF(SUM(R24:T24)>0,1,0) -> 0 | K24: =IF(SUM(U24:Y24)>0,1,0) -> 0 | L24: =IF(SUM(Z24:AC24)>0,1,0) -> 0 | M24: =IF(SUM(AD24:AF24)>0,1,0) -> 0 | N24: =IF(SUM(AG24:AH24)>0,1,0) -> 1 | O24: =IF(SUM(AI24:AL24)>0,1,0) -> 0 | P24: =IF(SUM(AM24:AQ24)>0,1,0) -> 0 | Q24: =IF(AR24>0,1,0) -> 0 | R24: 0 | S24: 0 | T24: 0 | U24: 0 | V24: 0 | W24: 0 | X24: 0 | Y24: 0 | Z24: 0 | AA24: 0 | AB24: 0 | AC24: 0 | AD24: 0 | AE24: 0 | AF24: 0 | AG24: 0 | AH24: 1 | AI24: 0 | AJ24: 0 | AK24: 0 | AL24: 0 | AM24: 0 | AN24: 0 | AO24: 0 | AP24: 0 | AQ24: 0 | AR24: 0 | AS24: =SUM(J24:Q24) -> 1 | AT24: =SUM(R24:AR24) -> 1 | AU24: 推荐价值判断 | AV24: =IF(AT24>0,1,0) -> 1 | AW24: =IF(AT24=0,1,0) -> 0 | AX24: =IF(AT24>=8,1,0) -> 0 | AY24: 3 | AZ24: 正面 | BA24: P | BB24: 原文
A25: CN-N-024 | B25: 中文 | C25: 不推荐 | D25: 186 | E25: 15 | F25: 6.5 | G25: 2024-08-20 | H25: 免费获取的产品 目前不推荐任何不喜欢魂游受虐模式的轻度路人玩家跟风买这个游戏。（这不是差评，是基于目前宣发狂热氛围下对轻度玩家的谨慎购入建议，别那么二极管/狭隘排外自卑）能做出来个没难度选项的纯背板的魂游我是真没想过的，前面大头娃起码背板个80%打过了，现在打个白衣居士被打到道心破碎，真没想到是个纯背板才能打得过的魂游，继承魂的体力条机制，365里路跑图，延迟滚，翻滚窗口滞连第二次，UI弄得贼小打起来根本没空注视体力条（要求熟练背板），武器机制要求 背死板，不然一点收益都吃不到，一点容错都没有，翻滚延迟考背板，要垫轻击的重击GP要背板，两个都TM有前摇延迟，判定窗口还贼短，打个BOSS要考跳跃、完美闪避、连招窗口，背板背板背得道心破碎了，但凡TM的翻滚没前摇都能爽起来，这一点起码加了90%的难度，傻逼玩意好学不学学TM魂游搞翻滚前摇延迟，我背完怪物出招时间点，背连招逻辑就算了，我还得背自己的输入延迟，TMD完美闪避的判定还TMD终极诡异，我纯战士翻滚打完1.0法环白金都没这么难受，法环那延迟滚都没这个诡异，考试也不上来就高强度考全科目，日NM的难度翻倍，不背板根本不能正常过关，要降难度只能去刷小怪攒经验升级加点，策划真要做魂游为什么不写明白，BOSS不仅性能碾压玩家，还会读指令，一些远程攻击还带穿模穿墙穿透的，还搞那么多地形凹凸，初见我被幽魂那穿墙射线整笑了还有那个独立的移动重击蓄力系统，我都搞不懂策划是怎么想出来这么割裂的招式，这游戏动作衔接就僵硬，因为没有招式取消后摇，必须播完动画帧，而单重击霸体没无敌时间，伤害能吃到饱，还得讲究背板输出窗口，那重击点攒起来就费劲，打空直接血亏，更别说那个要垫轻击的重击GP，我就没见过如此多施展条件的逆天招式，不是自由态施展，要垫刀，而轻击分5下，每下前后摇逐步增长，而闪避和衔接招式都要等攻击动作帧播完了才能派生下一招，而这个派生窗口还极短，还不能闪避打断/被打断（闪避继承连招拆进后期技能树了），导致凹一个重击GP，我先要费力完美闪避+蹭轻击攒一个重击点，然后还得专注背板读招在怪物身上找机会垫一刀轻击，然后再赌怪物会打我延迟重击的一瞬间，千辛万苦遇到窗口重击到了，那收益还不如不打GP直接平A攒重击点直接派生凹GP砸灌伤害，而怪物大概率快打完连招即将进入自由态，那很可能读指令后撤步，重击还是罚站原地释放的，攻击距离还短，而那些BOSS机动高，抬手还快，空GP砸棍直接血压拉满，而且觉得和连招系统巨割裂，仿佛这重击纯属是个偶尔放一下的战技。说是ARPG，但前期这个角色性能差得离谱，技能树一眼望到头，基本上玩死一种招式，战斗体验毫无深度，重击太割裂难用又要用，只能一直找输出窗口平A偷刀，而怪物性能却强到考全科目，装备类别也是经典木棍打小龙虾迭代，打得跟类魂一样，根本不能很爽的交互，这种机制数值不对等的难，游科有在乎过轻度玩家的体验？真觉得魂游市场很大？还是说宣发足够后“自有大儒为你辩经”？还有手柄震动几乎没有，锁定视角转速跟不上游戏里的BOSS各种飘逸移速然后是这个地图，问题可太大了，没有标志物，怪物貌似没掉落伤害但玩家有掉落伤害，而且一些在其他游戏中看着出去就死亡的场景，比如悬崖，一些边缘，河流，放这里面可能是另一条能走的岔路，而且还分不清是不是主线路还是支线路，十有八九还往里面藏BOSS，在线性箱庭里面藏大线性箱庭岔路，对于有经验的玩家极其不友好，谁知道你能不能走，是不是主线，有没有漏关键道具，谁知道你是惊喜还是惊吓，只能指望那个“防跌落”的空气墙动作去试探，然而真有落差却能过去的地方，却能把玩家摔掉血，指引只有在篝火点附近的主线一本道有光点指引，探图体验太晕了，这还是个有跑图压力的魂游，提心吊胆摸路还摸到迷路，虽说堆料，但游戏体验非常不舒服还好没脑子热跟风买，本以为是个爽快ACT，没想到是个没难度选项的纯纯背板受苦魂游，假如游科明说了是难度很高的类魂，那我不会在忙碌中挤出一天假期，但游科说这玩意是ARPG，网络宣发也说是类战神，再不济也是仁王，早起本以为能爽玩，没想到是坐大牢，有落差+状态不佳直接干到道心破碎，我不是不会练，而是在这个时间点我没这个心态给你凹，但凡你说是类魂，我就找周末静心来练，某些狭隘孝子，真觉得世界上就只有一种玩家？狭隘地认为自家第一个打响世界的神坛只配小部分高端精英玩家玩？这种人比单机婆罗门还恶臭，环境里的真正的搅屎棍，记住，你玩某个游戏时间长，很厉害，那只会证明你是一个很闲的闲人罢了，游戏里的你，再强大都是虚拟的。但游戏质量真是目前国内3A巅峰水准，极致的堆料，村里出来的第一个大学生，第一次肯定是有点缺点，国内游戏历程是有目共睹的，如今在落后世界好几年的畸形环境里终于诞生出一个，我是真心包容支持的，真心祝愿这游戏能吸纳玩家反馈优化不良体验变得更好，中国单机游戏能诞生更多优秀的作品，喜欢这游戏的天命人能游戏愉快。（这社媒宣发真离谱，一个个博主生怕吃不到流量，全在蹭热度，游戏还没出一天，就仗着先玩先录的素材争先恐后地把各种剧透各种攻略发上来，网都没法上了）（还有这边玩家群体的风气也离谱，一个游戏难玩，玩不爽，那应该先去质疑策划，提出游戏缺点，要求合理合法的游戏体验，游戏公司不妥协再考虑看攻略找轮椅/开挂降难度或者别玩，而不是第一时间下意识想到走捷径开挂作弊，把游戏厂商和其作品当成完全不容置疑的神） | I25: 免费获取的产品 目前不推荐任何不喜欢魂游受虐模式的轻度路人玩家跟风买这个游戏。（这不是差评，是基于目前宣发狂热氛围下对轻度玩家的谨慎购入建议，别那么二极管/狭隘排外自卑）能做出来个没难度选项的纯背板的魂游我是真没想过的，前面大头娃起码背板个80%打过了，现在打个白衣居士被打到道心破碎，真没想到是个纯背板才能打得过的魂游，继承魂的体力条机制，365里路跑图，延迟滚，翻滚窗口滞连第二次，UI弄得贼小打起来根本没空注视体力条（要求熟练背板），武器机制要求 背死板，不然一点收益都吃不到，一点容错都没有，翻滚延迟考背板，要垫轻击的重击GP要背板，两个都TM有前摇延迟，判定窗口还贼短，打个BOSS要考跳跃、完美闪避、连招窗口，背板背板背得道心破碎了，但凡TM的翻滚没前摇都能爽起来，这一点起码加了90%的难度，傻逼玩意好学不学学TM魂游搞翻滚前摇延迟，我背完怪物出招时间点，背连招逻辑就算了，我还得背自己的输入延迟，TMD完美闪避的判定还TMD终极诡异，我纯战士翻滚打完1.0法环白金都没这么难受，法环那延迟滚都没这个诡异，考试也不上来就高强度考全科目，日NM的难度翻倍，不背板根本不能正常过关，要降难度只能去刷小怪攒经验升级加点，策划真要做魂游为什么不写明白，BOSS不仅性能碾压玩家，还会读指令，一些远程攻击还带穿模穿墙穿透的，还搞那么多地形凹凸，初见我被幽魂那穿墙射线整笑了还有那个独立的移动重击蓄力系统，我都搞不懂策划是怎么想出来这么割裂的招式，这游戏动作衔接就僵硬，因为没有招式取消后摇，必须播完动画帧，而单重击霸体没无敌时间，伤害能吃到饱，还得讲究背板输出窗口，那重击点攒起来就费劲，打空直接血亏，更别说那个要垫轻击的重击GP，我就没见过如此多施展条件的逆天招式，不是自由态施展，要垫刀，而轻击分5下，每下前后摇逐步增长，而闪避和衔接招式都要等攻击动作帧播完了才能派生下一招，而这个派生窗口还极短，还不能闪避打断/被打断（闪避继承连招拆进后期技能树了），导致凹一个重击GP，我先要费力完美闪避+蹭轻击攒一个重击点，然后还得专注背板读招在怪物身上找机会垫一刀轻击，然后再赌怪物会打我延迟重击的一瞬间，千辛万苦遇到窗口重击到了，那收益还不如不打GP直接平A攒重击点直接派生凹GP砸灌伤害，而怪物大概率快打完连招即将进入自由态，那很可能读指令后撤步，重击还是罚站原地释放的，攻击距离还短，而那些BOSS机动高，抬手还快，空GP砸棍直接血压拉满，而且觉得和连招系统巨割裂，仿佛这重击纯属是个偶尔放一下的战技。说是ARPG，但前期这个角色性能差得离谱，技能树一眼望到头，基本上玩死一种招式，战斗体验毫无深度，重击太割裂难用又要用，只能一直找输出窗口平A偷刀，而怪物性能却强到考全科目，装备类别也是经典木棍打小龙虾迭代，打得跟类魂一样，根本不能很爽的交互，这种机制数值不对等的难，游科有在乎过轻度玩家的体验？真觉得魂游市场很大？还是说宣发足够后“自有大儒为你辩经”？还有手柄震动几乎没有，锁定视角转速跟不上游戏里的BOSS各种飘逸移速然后是这个地图，问题可太大了，没有标志物，怪物貌似没掉落伤害但玩家有掉落伤害，而且一些在其他游戏中看着出去就死亡的场景，比如悬崖，一些边缘，河流，放这里面可能是另一条能走的岔路，而且还分不清是不是主线路还是支线路，十有八九还往里面藏BOSS，在线性箱庭里面藏大线性箱庭岔路，对于有经验的玩家极其不友好，谁知道你能不能走，是不是主线，有没有漏关键道具，谁知道你是惊喜还是惊吓，只能指望那个“防跌落”的空气墙动作去试探，然而真有落差却能过去的地方，却能把玩家摔掉血，指引只有在篝火点附近的主线一本道有光点指引，探图体验太晕了，这还是个有跑图压力的魂游，提心吊胆摸路还摸到迷路，虽说堆料，但游戏体验非常不舒服还好没脑子热跟风买，本以为是个爽快ACT，没想到是个没难度选项的纯纯背板受苦魂游，假如游科明说了是难度很高的类魂，那我不会在忙碌中挤出一天假期，但游科说这玩意是ARPG，网络宣发也说是类战神，再不济也是仁王，早起本以为能爽玩，没想到是坐大牢，有落差+状态不佳直接干到道心破碎，我不是不会练，而是在这个时间点我没这个心态给你凹，但凡你说是类魂，我就找周末静心来练，某些狭隘孝子，真觉得世界上就只有一种玩家？狭隘地认为自家第一个打响世界的神坛只配小部分高端精英玩家玩？这种人比单机婆罗门还恶臭，环境里的真正的搅屎棍，记住，你玩某个游戏时间长，很厉害，那只会证明你是一个很闲的闲人罢了，游戏里的你，再强大都是虚拟的。但游戏质量真是目前国内3A巅峰水准，极致的堆料，村里出来的第一个大学生，第一次肯定是有点缺点，国内游戏历程是有目共睹的，如今在落后世界好几年的畸形环境里终于诞生出一个，我是真心包容支持的，真心祝愿这游戏能吸纳玩家反馈优化不良体验变得更好，中国单机游戏能诞生更多优秀的作品，喜欢这游戏的天命人能游戏愉快。（这社媒宣发真离谱，一个个博主生怕吃不到流量，全在蹭热度，游戏还没出一天，就仗着先玩先录的素材争先恐后地把各种剧透各种攻略发上来，网都没法上了）（还有这边玩家群体的风气也离谱，一个游戏难玩，玩不爽，那应该先去质疑策划，提出游戏缺点，要求合理合法的游戏体验，游戏公司不妥协再考虑看攻略找轮椅/开挂降难度或者别玩，而不是第一时间下意识想到走捷径开挂作弊，把游戏厂商和其作品当成完全不容置疑的神） | J25: =IF(SUM(R25:T25)>0,1,0) -> 1 | K25: =IF(SUM(U25:Y25)>0,1,0) -> 1 | L25: =IF(SUM(Z25:AC25)>0,1,0) -> 1 | M25: =IF(SUM(AD25:AF25)>0,1,0) -> 1 | N25: =IF(SUM(AG25:AH25)>0,1,0) -> 1 | O25: =IF(SUM(AI25:AL25)>0,1,0) -> 1 | P25: =IF(SUM(AM25:AQ25)>0,1,0) -> 1 | Q25: =IF(AR25>0,1,0) -> 0 | R25: 1 | S25: 0 | T25: 1 | U25: 1 | V25: 1 | W25: 1 | X25: 1 | Y25: 1 | Z25: 1 | AA25: 1 | AB25: 1 | AC25: 1 | AD25: 1 | AE25: 0 | AF25: 0 | AG25: 1 | AH25: 1 | AI25: 1 | AJ25: 0 | AK25: 1 | AL25: 0 | AM25: 0 | AN25: 0 | AO25: 0 | AP25: 1 | AQ25: 0 | AR25: 0 | AS25: =SUM(J25:Q25) -> 7 | AT25: =SUM(R25:AR25) -> 17 | AU25: 画面美术场景；演出角色怪物设计；动作打击手感；Boss战斗节奏；难度挑战；锁定视角；判定反馈；地图路线；空气墙可达性；探索隐藏支线；引导迷路单线；优化帧率；整体完成度；推荐价值判断；西游悟空符号；本国媒介路径；外部资料依赖 | AV25: =IF(AT25>0,1,0) -> 1 | AW25: =IF(AT25=0,1,0) -> 0 | AX25: =IF(AT25>=8,1,0) -> 1 | AY25: -3.5 | AZ25: 负面 | BA25: N | BB25: 原文
